<?xml version="1.0" ?>
<!-- =================================================================================== -->
<!-- |    This document was autogenerated by xacro from /home/gauss/projects/personal_ws/src/battery_cell/battery_cell_description/urdf/battery_cell_rviz.xacro | -->
<!-- |    EDITING THIS FILE BY HAND IS NOT RECOMMENDED                                 | -->
<!-- =================================================================================== -->
<robot name="battery_cell">
    <link name="world" />
    <link name="structure_base_link">
        <inertial>
            <origin rpy="0 0 0" xyz="0.035817 -0.1978 -1.2121E-05" />
            <mass value="780.97" />
            <inertia ixx="25.789" ixy="-0.0076742" ixz="0.0023584" iyy="48.078" iyz="2.5193E-05" izz="33.648" />
        </inertial>
        <visual>
            <origin rpy="0 0 0" xyz="0 0 0" />
            <geometry>
                <mesh filename="package://kuka_structure_description/meshes/base_link.STL" scale="0.001 0.001 0.001" />
            </geometry>
            <material name="">
                <color rgba="1 0 0 1" />
            </material>
        </visual>
        <collision>
            <origin rpy="0 0 0" xyz="0 0 0" />
            <geometry>
                <mesh filename="package://kuka_structure_description/meshes/base_link.STL" scale="0.001 0.001 0.001" />
            </geometry>
        </collision>
    </link>
    <link name="structure_link_1">
        <inertial>
            <origin rpy="0 0 0" xyz="-0.28012 0.38938 0.024882" />
            <mass value="660.35" />
            <inertia ixx="38.274" ixy="9.9756" ixz="-0.5181" iyy="36.77" iyz="0.16531" izz="32.584" />
        </inertial>
        <visual>
            <origin rpy="0 0 0" xyz="0 0 0" />
            <geometry>
                <mesh filename="package://kuka_structure_description/meshes/link_1.STL" scale="0.001 0.001 0.001" />
            </geometry>
            <material name="">
                <color rgba="1 0 0 1" />
            </material>
        </visual>
        <collision>
            <origin rpy="0 0 0" xyz="0 0 0" />
            <geometry>
                <mesh filename="package://kuka_structure_description/meshes/link_1.STL" scale="0.001 0.001 0.001" />
            </geometry>
        </collision>
    </link>
    <!-- <joint name="${prefix}joint_1" type="prismatic"> -->
    <joint name="structure_joint_1" type="fixed">
        <origin rpy="0 0 0" xyz="-0.250 0.215 2.720" />
        <parent link="structure_base_link" />
        <child link="structure_link_1" />
        <axis xyz="1 0 0" />
        <limit effort="100000" lower="0" upper="2.9" velocity="1.74533" />
    </joint>
    <!-- current position -->
    <!-- <joint name="${prefix}joint_1" type="fixed">
    <origin
      xyz="0.850 0.215 2.720"
      rpy="0 0 0" />
    <parent
      link="${prefix}base_link" />
    <child
      link="${prefix}link_1" />
    <axis
      xyz="-1 0 0" />
    <limit
      lower="0"
      upper="30000000000000.0"
      effort="${joint_1_eff_limit}"
      velocity="${joint_1_vel_limit}" />
  </joint> -->
    <!-- end current position -->
    <transmission name="structure_tran_1">
        <type>transmission_interface/SimpleTransmission</type>
        <joint name="structure_joint_1">
            <hardwareInterface>hardware_interface/EffortJointInterface</hardwareInterface>
        </joint>
        <actuator name="structure_motor_1">
            <mechanicalReduction>1</mechanicalReduction>
        </actuator>
    </transmission>
    <!-- <xacro:property name="joint1_pos_upper_limit" value="3.22886" />     185° -->
    <!-- <xacro:property name="joint1_pos_lower_limit" value="-3.22886" />   -185° -->
    <!-- <xacro:property name="joint2_pos_upper_limit" value="1.0472" />       60° -->
    <!-- <xacro:property name="joint2_pos_lower_limit" value="-3.05433" />   -175° -->
    <!-- <xacro:property name="joint3_pos_upper_limit" value="2.96706" />     170° -->
    <!-- <xacro:property name="joint3_pos_lower_limit" value="-2.0944" />    -120° -->
    <!-- <xacro:property name="joint4_pos_upper_limit" value="3.14159" />     180° -->
    <!-- <xacro:property name="joint4_pos_lower_limit" value="-3.14159" />   -180° -->
    <!-- <xacro:property name="joint5_pos_upper_limit" value="2.18166" />     125° -->
    <!-- <xacro:property name="joint5_pos_lower_limit" value="-2.18166" />   -125° -->
    <!-- <xacro:property name="joint6_pos_upper_limit" value="6.10865" />     350° -->
    <!-- <xacro:property name="joint6_pos_lower_limit" value="-6.10865" />   -350° -->
    <!-- -190° -->
    <!--  360°/s -->
    <link concave="yes" name="kuka_base_link">
        <inertial>
            <origin rpy="0 0 0" xyz="-0.080585 0.00067592 0.086754" />
            <mass value="30.385" />
            <inertia ixx="0.38941" ixy="0.0047083" ixz="0.060696" iyy="0.87424" iyz="-0.00029206" izz="1.0819" />
        </inertial>
        <visual>
            <origin rpy="0 0 0" xyz="0 0 0" />
            <geometry>
                <mesh filename="package://kr_50_r2500_description/meshes/base_link.STL" />
            </geometry>
            <material name="">
                <color rgba="0.79216 0.81961 0.93333 1" />
            </material>
        </visual>
        <collision concave="yes">
            <origin rpy="0 0 0" xyz="0 0 0" />
            <geometry>
                <mesh filename="package://kr_50_r2500_description/meshes/base_link.STL" />
            </geometry>
        </collision>
    </link>
    <link concave="yes" name="kuka_link1">
        <inertial>
            <origin rpy="0 0 0" xyz="0.0600446329714386 0.0116665626627102 0.247062352627269" />
            <mass value="56.0953515273858" />
            <inertia ixx="1.7123503270672" ixy="0.020886843872196" ixz="-0.525246219592262" iyy="2.15349859010488" iyz="-0.031415061955379" izz="1.31690706549715" />
        </inertial>
        <visual>
            <origin rpy="0 0 0" xyz="0 0 0" />
            <geometry>
                <mesh filename="package://kr_50_r2500_description/meshes/link1.STL" />
            </geometry>
            <material name="">
                <color rgba="0.792156862745098 0.819607843137255 0.933333333333333 1" />
            </material>
        </visual>
        <collision concave="yes">
            <origin rpy="0 0 0" xyz="0 0 0" />
            <geometry>
                <mesh filename="package://kr_50_r2500_description/meshes/link1.STL" />
            </geometry>
        </collision>
    </link>
    <joint name="kuka_joint1" type="revolute">
        <origin rpy="1.5708 0.009141 0" xyz="0 -0.17 0" />
        <parent link="kuka_base_link" />
        <child link="kuka_link1" />
        <axis xyz="0 0 -1" />
        <limit effort="10000" lower="-3.22886" upper="3.22886" velocity="3.05433" />
    </joint>
    <link concave="yes" name="kuka_link2">
        <inertial>
            <origin rpy="0 0 0" xyz="0.0040251350126134 -0.177497207044946 0.578963319749875" />
            <mass value="35.5942562362571" />
            <inertia ixx="4.47662495992728" ixy="-0.00203441583192867" ixz="0.0769841500591921" iyy="4.49958249588231" iyz="0.214283202316168" izz="0.238618624180958" />
        </inertial>
        <visual>
            <origin rpy="0 0 0" xyz="0 0 0" />
            <geometry>
                <mesh filename="package://kr_50_r2500_description/meshes/link2.STL" />
            </geometry>
            <material name="">
                <color rgba="0.792156862745098 0.819607843137255 0.933333333333333 1" />
            </material>
        </visual>
        <collision concave="yes">
            <origin rpy="0 0 0" xyz="0 0 0" />
            <geometry>
                <mesh filename="package://kr_50_r2500_description/meshes/link2.STL" />
            </geometry>
        </collision>
    </link>
    <joint name="kuka_joint2" type="revolute">
        <origin rpy="0 1.557055  0" xyz="0.175 -0.074807 0.405" />
        <parent link="kuka_link1" />
        <child link="kuka_link2" />
        <axis xyz="0 1 0" />
        <limit effort="10000" lower="-3.05433" upper="1.0472" velocity="2.75762" />
    </joint>
    <link concave="yes" name="kuka_link3">
        <inertial>
            <origin rpy="0 0 0" xyz="0.0305175734183824 0.097105360534718 0.0162382856824868" />
            <mass value="36.6784876951283" />
            <inertia ixx="0.563908772434098" ixy="0.0648382829251099" ixz="-0.0822356915818992" iyy="0.7868662787778" iyz="0.00379928707270628" izz="1.01511384262152" />
        </inertial>
        <visual>
            <origin rpy="0 0 0" xyz="0 0 0" />
            <geometry>
                <mesh filename="package://kr_50_r2500_description/meshes/link3.STL" />
            </geometry>
            <material name="">
                <color rgba="0.792156862745098 0.819607843137255 0.933333333333333 1" />
            </material>
        </visual>
        <collision concave="yes">
            <origin rpy="0 0 0" xyz="0 0 0" />
            <geometry>
                <mesh filename="package://kr_50_r2500_description/meshes/link3.STL" />
            </geometry>
        </collision>
    </link>
    <joint name="kuka_joint3" type="revolute">
        <origin rpy="0 -1.557055 0" xyz="0 0 1.29" />
        <parent link="kuka_link2" />
        <child link="kuka_link3" />
        <axis xyz="0 1 0" />
        <limit effort="10000" lower="-2.0944" upper="2.96706" velocity="3.05433" />
    </joint>
    <link concave="yes" name="kuka_link4">
        <inertial>
            <origin rpy="0 0 0" xyz="0.400085577392824 0.0280533450779974 -6.01461215805621E-05" />
            <mass value="15.1542881051753" />
            <inertia ixx="0.0701060691297577" ixy="-0.0990093812478981" ixz="0.00018489912158269" iyy="0.729933929975417" iyz="-2.55452640777306E-05" izz="0.748398699396793" />
        </inertial>
        <visual>
            <origin rpy="0 0 0" xyz="0 0 0" />
            <geometry>
                <mesh filename="package://kr_50_r2500_description/meshes/link4.STL" />
            </geometry>
            <material name="">
                <color rgba="0.792156862745098 0.819607843137255 0.933333333333333 1" />
            </material>
        </visual>
        <collision concave="yes">
            <origin rpy="0 0 0" xyz="0 0 0" />
            <geometry>
                <mesh filename="package://kr_50_r2500_description/meshes/link4.STL" />
            </geometry>
        </collision>
    </link>
    <joint name="kuka_joint4" type="revolute">
        <origin rpy="0 0 0" xyz="0.32687 0.074807 0.05" />
        <parent link="kuka_link3" />
        <child link="kuka_link4" />
        <axis xyz="-1 0 0" />
        <limit effort="10000" lower="-2.79253" upper="2.79253" velocity="4.36332" />
    </joint>
    <link concave="yes" name="kuka_link5">
        <inertial>
            <origin rpy="0 0 0" xyz="0.0348166227286741 -0.0333672873060013 -7.86869120463773E-05" />
            <mass value="5.17490767884354" />
            <inertia ixx="0.0198943557123769" ixy="-0.00379528838423929" ixz="-3.17734786601442E-05" iyy="0.0325404927644558" iyz="2.0392665049925E-05" izz="0.0334468145607699" />
        </inertial>
        <visual>
            <origin rpy="0 0 0" xyz="0 0 0" />
            <geometry>
                <mesh filename="package://kr_50_r2500_description/meshes/link5.STL" />
            </geometry>
            <material name="">
                <color rgba="0.792156862745098 0.819607843137255 0.933333333333333 1" />
            </material>
        </visual>
        <collision concave="yes">
            <origin rpy="0 0 0" xyz="0 0 0" />
            <geometry>
                <mesh filename="package://kr_50_r2500_description/meshes/link5.STL" />
            </geometry>
        </collision>
    </link>
    <joint name="kuka_joint5" type="revolute">
        <origin rpy="0 -0.0 0" xyz="0.708131634616243 0 0" />
        <parent link="kuka_link4" />
        <child link="kuka_link5" />
        <axis xyz="0 1 0" />
        <limit effort="10000" lower="-2.18166" upper="2.18166" velocity="4.36332" />
    </joint>
    <link concave="yes" name="kuka_link6">
        <inertial>
            <origin rpy="0 0 0" xyz="0.0697663509698883 -2.97159715269453E-06 -4.15148219581329E-05" />
            <mass value="0.362972835401582" />
            <inertia ixx="0.000809216081686161" ixy="9.97029573660496E-10" ixz="2.41841688721677E-07" iyy="0.000440777200154296" iyz="1.15745872636665E-07" izz="0.000441694717362902" />
        </inertial>
        <visual>
            <origin rpy="0 0 0" xyz="0 0 0" />
            <geometry>
                <mesh filename="package://kr_50_r2500_description/meshes/link6.STL" />
            </geometry>
            <material name="">
                <color rgba="0.792156862745098 0.819607843137255 0.933333333333333 1" />
            </material>
        </visual>
        <collision concave="yes">
            <origin rpy="0 0 0" xyz="0 0 0" />
            <geometry>
                <mesh filename="package://kr_50_r2500_description/meshes/link6.STL" />
            </geometry>
        </collision>
    </link>
    <joint name="kuka_joint6" type="revolute">
        <origin rpy="0 0 0" xyz="0.0966663727881543 0 0" />
        <parent link="kuka_link5" />
        <child link="kuka_link6" />
        <axis xyz="-1 0 0" />
        <limit effort="10000" lower="-3.31613" upper="3.31613" velocity="6.28319" />
    </joint>
    <joint name="kuka_link6_to_flange" type="fixed">
        <origin rpy="0 1.57079632679 0" xyz="0.07 0 0" />
        <parent link="kuka_link6" />
        <child link="kuka_flange" />
    </joint>
    <link name="kuka_flange">
        <inertial>
            <origin rpy="0 0 0" xyz="0 0 0" />
            <mass value="0.01" />
            <inertia ixx="0.0001" ixy="0.0000" ixz="0.0000" iyy="0.0001" iyz="0.0000" izz="0.0001" />
        </inertial>
    </link>
    <transmission name="kuka_tran1">
        <type>transmission_interface/SimpleTransmission</type>
        <joint name="kuka_joint1">
            <hardwareInterface>hardware_interface/EffortJointInterface</hardwareInterface>
        </joint>
        <actuator name="kuka_motor1">
            <mechanicalReduction>1</mechanicalReduction>
            <hardwareInterface>hardware_interface/EffortJointInterface</hardwareInterface>
        </actuator>
    </transmission>
    <transmission name="kuka_tran2">
        <type>transmission_interface/SimpleTransmission</type>
        <joint name="kuka_joint2">
            <hardwareInterface>hardware_interface/EffortJointInterface</hardwareInterface>
        </joint>
        <actuator name="kuka_motor2">
            <mechanicalReduction>1</mechanicalReduction>
            <hardwareInterface>hardware_interface/EffortJointInterface</hardwareInterface>
        </actuator>
    </transmission>
    <transmission name="kuka_tran3">
        <type>transmission_interface/SimpleTransmission</type>
        <joint name="kuka_joint3">
            <hardwareInterface>hardware_interface/EffortJointInterface</hardwareInterface>
        </joint>
        <actuator name="kuka_motor3">
            <mechanicalReduction>1</mechanicalReduction>
            <hardwareInterface>hardware_interface/EffortJointInterface</hardwareInterface>
        </actuator>
    </transmission>
    <transmission name="kuka_tran4">
        <type>transmission_interface/SimpleTransmission</type>
        <joint name="kuka_joint4">
            <hardwareInterface>hardware_interface/EffortJointInterface</hardwareInterface>
        </joint>
        <actuator name="kuka_motor4">
            <mechanicalReduction>1</mechanicalReduction>
            <hardwareInterface>hardware_interface/EffortJointInterface</hardwareInterface>
        </actuator>
    </transmission>
    <transmission name="kuka_tran5">
        <type>transmission_interface/SimpleTransmission</type>
        <joint name="kuka_joint5">
            <hardwareInterface>hardware_interface/EffortJointInterface</hardwareInterface>
        </joint>
        <actuator name="kuka_motor5">
            <mechanicalReduction>1</mechanicalReduction>
            <hardwareInterface>hardware_interface/EffortJointInterface</hardwareInterface>
        </actuator>
    </transmission>
    <transmission name="kuka_tran6">
        <type>transmission_interface/SimpleTransmission</type>
        <joint name="kuka_joint6">
            <hardwareInterface>hardware_interface/EffortJointInterface</hardwareInterface>
        </joint>
        <actuator name="kuka_motor6">
            <mechanicalReduction>1</mechanicalReduction>
            <hardwareInterface>hardware_interface/EffortJointInterface</hardwareInterface>
        </actuator>
    </transmission>
    <link concave="yes" name="gripper_base">
        <inertial>
            <origin rpy="0 0 0" xyz="0.00002849 -0.00022471 0.03657638" />
            <mass value="0.6818" />
            <inertia ixx="0.00154456" ixy="0.00000154" ixz="0.00000118" iyy="0.00283260" iyz="-0.00000405" izz="0.00195998" />
        </inertial>
        <visual>
            <origin rpy="0 0 0" xyz="0 0 0" />
            <geometry>
                <mesh filename="package://schunk_gripper_jpg_p_160_description/meshes/SCHUNK_parallel_gripper_base.STL" />
            </geometry>
            <material name="">
                <color rgba="0.79216 0.81961 0.93333 1" />
            </material>
        </visual>
        <collision concave="yes">
            <origin rpy="0 0 0" xyz="0 0 0" />
            <geometry>
                <mesh filename="package://schunk_gripper_jpg_p_160_description/meshes/SCHUNK_parallel_gripper_base.STL" />
            </geometry>
        </collision>
    </link>
    <joint name="gripper_left_joint" type="prismatic">
        <origin rpy="0 0 0" xyz="0.0006 0 0.0481" />
        <parent link="gripper_base" />
        <child link="gripper_left_slider" />
        <axis xyz="1 0 0" />
        <limit effort="1000" lower="0.000" upper="0.017" velocity="1000000" />
        <mimic joint="gripper_left_joint_circle" multiplier="0.05" offset="-0.00086" />
    </joint>
    <link concave="yes" name="gripper_left_slider">
        <inertial>
            <origin rpy="0 0 0" xyz="0.03936113 -0.00000000 0.01237203" />
            <mass value="0.070" />
            <inertia ixx="0.00002269" ixy="0.00000000" ixz="0.00003426" iyy="0.00015861" iyz="-0.00000000" izz="0.00015142" />
        </inertial>
        <visual>
            <origin rpy="0 0 0" xyz="0 0 0" />
            <geometry>
                <mesh filename="package://schunk_gripper_jpg_p_160_description/meshes/SCHUNK_parallel_gripper_finger_slider.STL" />
            </geometry>
            <material name="">
                <color rgba="0.79216 0.81961 0.93333 1" />
            </material>
        </visual>
        <collision concave="yes">
            <origin rpy="0 0 0" xyz="0 0 0" />
            <geometry>
                <mesh filename="package://schunk_gripper_jpg_p_160_description/meshes/SCHUNK_parallel_gripper_finger_slider.STL" />
            </geometry>
        </collision>
    </link>
    <joint name="gripper_right_joint" type="prismatic">
        <origin rpy="0 0 3.14159" xyz="-0.0006 0 0.0481" />
        <parent link="gripper_base" />
        <child link="gripper_right_slider" />
        <axis xyz="1 0 0" />
        <limit effort="100000" lower="0.000" upper="0.017" velocity="1000000" />
        <mimic joint="gripper_left_joint" multiplier="1" offset="0" />
    </joint>
    <link concave="yes" name="gripper_right_slider">
        <inertial>
            <origin rpy="0 0 0" xyz="0.03936113 -0.00000000 0.01237203" />
            <mass value="0.070" />
            <inertia ixx="0.00002269" ixy="0.00000000" ixz="0.00003426" iyy="0.00015861" iyz="-0.00000000" izz="0.00015142" />
        </inertial>
        <visual>
            <origin rpy="0 0 0" xyz="0 0 0" />
            <geometry>
                <mesh filename="package://schunk_gripper_jpg_p_160_description/meshes/SCHUNK_parallel_gripper_finger_slider.STL" />
            </geometry>
            <material name="">
                <color rgba="0.79216 0.81961 0.93333 1" />
            </material>
        </visual>
        <collision concave="yes">
            <origin rpy="0 0 0" xyz="0 0 0" />
            <geometry>
                <mesh filename="package://schunk_gripper_jpg_p_160_description/meshes/SCHUNK_parallel_gripper_finger_slider.STL" />
            </geometry>
        </collision>
    </link>
    <joint name="gripper_left_finger_joint" type="fixed">
        <origin rpy="0 0 3.14159" xyz="0.0285 0 0.0289" />
        <parent link="gripper_left_slider" />
        <child link="gripper_left_finger" />
        <axis xyz="0 0 0" />
    </joint>
    <link concave="yes" name="gripper_left_finger">
        <inertial>
            <origin rpy="0 0 0" xyz="-0.01665438 -0.00000438 0.05348249" />
            <mass value="0.10" />
            <inertia ixx="0.00041666" ixy="-0.00000001" ixz="-0.00005970" iyy="0.00047996" iyz="-0.00000004" izz="0.00007666" />
        </inertial>
        <visual>
            <origin rpy="0 0 0" xyz="0 0 0" />
            <geometry>
                <mesh filename="package://schunk_gripper_jpg_p_160_description/meshes/Finger.STL" />
            </geometry>
            <material name="">
                <color rgba="0.79216 0.81961 0.93333 1" />
            </material>
        </visual>
        <collision concave="yes">
            <origin rpy="0 0 0" xyz="0 0 0" />
            <geometry>
                <mesh filename="package://schunk_gripper_jpg_p_160_description/meshes/Finger.STL" />
            </geometry>
        </collision>
    </link>
    <joint name="gripper_right_finger_joint" type="fixed">
        <origin rpy="0 0 3.14159" xyz="0.0285 0 0.0289" />
        <parent link="gripper_right_slider" />
        <child link="gripper_right_finger" />
        <axis xyz="0 0 0" />
    </joint>
    <link concave="yes" name="gripper_right_finger">
        <inertial>
            <origin rpy="0 0 0" xyz="-0.01665438 -0.00000438 0.05348249" />
            <mass value="0.10" />
            <inertia ixx="0.00041666" ixy="-0.00000001" ixz="-0.00005970" iyy="0.00047996" iyz="-0.00000004" izz="0.00007666" />
        </inertial>
        <visual>
            <origin rpy="0 0 0" xyz="0 0 0" />
            <geometry>
                <mesh filename="package://schunk_gripper_jpg_p_160_description/meshes/Finger.STL" />
            </geometry>
            <material name="">
                <color rgba="0.79216 0.81961 0.93333 1" />
            </material>
        </visual>
        <collision concave="yes">
            <origin rpy="0 0 0" xyz="0 0 0" />
            <geometry>
                <mesh filename="package://schunk_gripper_jpg_p_160_description/meshes/Finger.STL" />
            </geometry>
        </collision>
    </link>
    <joint name="gripper_working_point_joint" type="fixed">
        <origin rpy="0 0 0" xyz="0.0 0 0.163" />
        <parent link="gripper_base" />
        <child link="gripper_working_point" />
        <axis xyz="0 0 0" />
    </joint>
    <link name="gripper_working_point" />
    <transmission name="gripper_left_joint_trans">
        <type>transmission_interface/SimpleTransmission</type>
        <joint name="gripper_left_joint_circle">
            <hardwareInterface>hardware_interface/EffortJointInterface</hardwareInterface>
        </joint>
        <actuator name="gripper_left_joint_motor">
            <mechanicalReduction>1</mechanicalReduction>
            <hardwareInterface>hardware_interface/EffortJointInterface</hardwareInterface>
        </actuator>
    </transmission>
    <transmission name="gripper_right_joint_trans">
        <type>transmission_interface/SimpleTransmission</type>
        <joint name="gripper_right_joint_circle">
            <hardwareInterface>hardware_interface/EffortJointInterface</hardwareInterface>
        </joint>
        <actuator name="gripper_right_joint_motor">
            <mechanicalReduction>1</mechanicalReduction>
            <hardwareInterface>hardware_interface/EffortJointInterface</hardwareInterface>
        </actuator>
    </transmission>
    <joint name="gripper_left_joint_circle" type="revolute">
        <origin rpy="0 0.0 0" xyz="0.0 0.0 0.0" />
        <parent link="gripper_base" />
        <child link="gripper_left_circle" />
        <axis xyz="0 1 0" />
        <limit effort="10000" lower="-100" upper="100" velocity="1000" />
    </joint>
    <link name="gripper_left_circle">
        <inertial>
            <origin rpy="0 0 0" xyz="0.0 -0.0 0.0" />
            <mass value="0.0001" />
            <inertia ixx="0.000001" ixy="0.0" ixz="0.0" iyy="0.000001" iyz="-0.0" izz="0.000001" />
        </inertial>
    </link>
    <joint name="gripper_right_joint_circle" type="revolute">
        <origin rpy="0 0.0 0" xyz="0.0 0.0 0.0" />
        <parent link="gripper_base" />
        <child link="gripper_right_circle" />
        <axis xyz="0 1 0" />
        <limit effort="10000" lower="-100" upper="100" velocity="1000" />
    </joint>
    <link name="gripper_right_circle">
        <inertial>
            <origin rpy="0 0 0" xyz="0.0 -0.0 0.0" />
            <mass value="0.0001" />
            <inertia ixx="0.000001" ixy="0.0" ixz="0.0" iyy="0.000001" iyz="-0.0" izz="0.000001" />
        </inertial>
    </link>
    <joint name="gripper_middle_left_joint_circle" type="prismatic">
        <origin rpy="0 0 0" xyz="0 0 0" />
        <parent link="gripper_left_circle" />
        <child link="gripper_middle_left_circle" />
        <axis xyz="0 0 1" />
        <limit effort="10000" lower="-1" upper="1" velocity="1000" />
    </joint>
    <link name="gripper_middle_left_circle">
        <inertial>
            <origin rpy="0 0 0" xyz="0.0 -0.0 0.0" />
            <mass value="0.0001" />
            <inertia ixx="0.000001" ixy="0.0" ixz="0.0" iyy="0.000001" iyz="-0.0" izz="0.000001" />
        </inertial>
    </link>
    <joint name="gripper_end_left_joint_circle" type="revolute">
        <origin rpy="0 0 0" xyz="0.0 0.0 0.0" />
        <parent link="gripper_middle_left_circle" />
        <child link="gripper_end_left_circle" />
        <axis xyz="0 1 0" />
        <limit effort="1000" lower="-200" upper="200" velocity="1000" />
    </joint>
    <link name="gripper_end_left_circle">
        <inertial>
            <origin rpy="0 0 0" xyz="0.0 -0.0 0.0" />
            <mass value="0.0001" />
            <inertia ixx="0.000001" ixy="0.0" ixz="0.0" iyy="0.000001" iyz="-0.0" izz="0.000001" />
        </inertial>
        <visual>
            <origin rpy="0 0 0" xyz="0 0 0" />
            <geometry>
                <box size="0.01 0.05 0.01" />
            </geometry>
            <material name="">
                <color rgba="0.79216 0.81961 0.93333 1" />
            </material>
        </visual>
    </link>
    <joint name="gripper_middle_right_joint_circle" type="prismatic">
        <origin rpy="0 0 0" xyz="0 0 0" />
        <parent link="gripper_right_circle" />
        <child link="gripper_middle_right_circle" />
        <axis xyz="0 0 1" />
        <limit effort="10000" lower="-1" upper="1" velocity="1000" />
    </joint>
    <link name="gripper_middle_right_circle">
        <inertial>
            <origin rpy="0 0 0" xyz="0.0 -0.0 0.0" />
            <mass value="0.0001" />
            <inertia ixx="0.000001" ixy="0.0" ixz="0.0" iyy="0.000001" iyz="-0.0" izz="0.000001" />
        </inertial>
    </link>
    <joint name="gripper_end_right_joint_circle" type="revolute">
        <origin rpy="0 0 0" xyz="0.0 0.0 0.0" />
        <parent link="gripper_middle_right_circle" />
        <child link="gripper_end_right_circle" />
        <axis xyz="0 1 0" />
        <limit effort="1000" lower="-200" upper="200" velocity="1000" />
    </joint>
    <link name="gripper_end_right_circle">
        <inertial>
            <origin rpy="0 0 0" xyz="0.0 -0.0 0.0" />
            <mass value="0.0001" />
            <inertia ixx="0.000001" ixy="0.0" ixz="0.0" iyy="0.000001" iyz="-0.0" izz="0.000001" />
        </inertial>
        <visual>
            <origin rpy="0 0 0" xyz="0 0 0" />
            <geometry>
                <box size="0.01 0.05 0.01" />
            </geometry>
            <material name="">
                <color rgba="0.79216 0.81961 0.93333 1" />
            </material>
        </visual>
    </link>
    <joint name="kuka_structure_to_kr_50_r2500" type="fixed">
        <origin rpy="0 1.5707963267948966 0" xyz="0.333 -0.035 0.325" />
        <parent link="structure_link_1" />
        <child link="kuka_base_link" />
    </joint>
    <joint name="kuka_robot_to_sensor_flange1" type="fixed">
        <origin rpy="0 0 1.5708" xyz="0 0 0" />
        <parent link="kuka_flange" />
        <child link="kuka_sensor_flange1" />
    </joint>
    <link name="kuka_sensor_flange1">
        <inertial>
            <origin rpy="0 0 0" xyz="-0 0 0.0094" />
            <mass value="0.365" />
            <inertia ixx="0.00052332" ixy="0.00000000" ixz="0.00000000" iyy="0.00052259" iyz="0.00000002" izz="0.00094820" />
        </inertial>
        <visual>
            <origin rpy="0 0 0" xyz="0 0 0" />
            <geometry>
                <mesh filename="package://battery_cell_description/meshes/sensor_flange_robot_side.STL" />
            </geometry>
            <material name="">
                <color rgba="0.792156862745098 0.819607843137255 0.933333333333333 1" />
            </material>
        </visual>
        <collision>
            <origin rpy="0 0 0" xyz="0 0 0" />
            <geometry>
                <mesh filename="package://battery_cell_description/meshes/sensor_flange_robot_side.STL" />
            </geometry>
        </collision>
    </link>
    <joint name="kuka_sensor_flange1_sensor_flange2" type="fixed">
        <origin rpy="0 0 0" xyz="0 0 0.02" />
        <parent link="kuka_sensor_flange1" />
        <child link="kuka_sensor_flange2" />
    </joint>
    <link name="kuka_sensor_flange2">
        <inertial>
            <origin rpy="0 0 0" xyz="0 -0.00000241 0.01069809" />
            <mass value="0.337" />
            <inertia ixx="0.00052069" ixy="0.00000000" ixz="0.00000000" iyy="0.00052072" iyz="0.00000005" izz="0.00094051" />
        </inertial>
        <visual>
            <origin rpy="0 0 0" xyz="0 0 0" />
            <geometry>
                <mesh filename="package://battery_cell_description/meshes/sensor_flange_sensor_side.STL" />
            </geometry>
            <material name="">
                <color rgba="0.792156862745098 0.819607843137255 0.933333333333333 1" />
            </material>
        </visual>
        <collision>
            <origin rpy="0 0 0" xyz="0 0 0" />
            <geometry>
                <mesh filename="package://battery_cell_description/meshes/sensor_flange_sensor_side.STL" />
            </geometry>
        </collision>
    </link>
    <joint name="kuka_sensor_flange2_to_sensor" type="fixed">
        <origin rpy="0 0 0" xyz="0 0 0.02" />
        <parent link="kuka_sensor_flange2" />
        <child link="kuka_sensor" />
    </joint>
    <link name="kuka_sensor">
        <inertial>
            <origin rpy="0 0 0" xyz="0 -0.00008976 0.01514808" />
            <mass value="0.169" />
            <inertia ixx="0.00014141" ixy="0.00000000" ixz="0.00000000" iyy="0.00014192" iyz="-0.00000021" izz="0.00018592" />
        </inertial>
        <visual>
            <origin rpy="0 0 0" xyz="0 0 0" />
            <geometry>
                <mesh filename="package://battery_cell_description/meshes/sensor.STL" />
            </geometry>
            <material name="">
                <color rgba="0.792156862745098 0.819607843137255 0.933333333333333 1" />
            </material>
        </visual>
        <collision>
            <origin rpy="0 0 0" xyz="0 0 0" />
            <geometry>
                <mesh filename="package://battery_cell_description/meshes/sensor.STL" />
            </geometry>
        </collision>
    </link>
    <joint name="kuka_sensor_to_gripper_flange" type="fixed">
        <origin rpy="0 0 0" xyz="0 0 0.0286" />
        <parent link="kuka_sensor" />
        <child link="kuka_gripper_flange" />
    </joint>
    <link name="kuka_gripper_flange">
        <inertial>
            <origin rpy="0 0 0" xyz="0 0.00001675 0.00750175" />
            <mass value="0.12657298" />
            <inertia ixx="0.00006223" ixy="-0.00000035" ixz="0.00000000" iyy="0.00016947" iyz="-0.00000000" izz="0.00021258" />
        </inertial>
        <visual>
            <origin rpy="0 0 0" xyz="0 0 0" />
            <geometry>
                <mesh filename="package://schunk_gripper_jpg_p_160_description/meshes/sensor_to_gripper_flange.STL" />
            </geometry>
            <material name="">
                <color rgba="0.792156862745098 0.819607843137255 0.933333333333333 1" />
            </material>
        </visual>
        <collision>
            <origin rpy="0 0 0" xyz="0 0 0" />
            <geometry>
                <mesh filename="package://schunk_gripper_jpg_p_160_description/meshes/sensor_to_gripper_flange.STL" />
            </geometry>
        </collision>
    </link>
    <joint name="gripper_joint" type="fixed">
        <origin rpy="0 0 0" xyz="0 0 0.015" />
        <parent link="kuka_gripper_flange" />
        <child link="gripper_base" />
    </joint>
    <joint name="kuka_fake_structure_right_foot" type="fixed">
        <origin rpy="0 0 0" xyz="-0.05 -0.05 0" />
        <parent link="structure_base_link" />
        <child link="structure_fake_structure_right_foot" />
    </joint>
    <link name="structure_fake_structure_right_foot">
        <inertial>
            <origin rpy="0 0 0" xyz="0 0 00" />
            <mass value="10000" />
            <inertia ixx="0.1" ixy="0.0" ixz="0.0" iyy="0.1" iyz="0.0" izz="0.1" />
        </inertial>
        <visual>
            <origin rpy="0 0 0" xyz="0.435 0.75 0.65" />
            <geometry>
                <box size="0.87 1.5 1.3" />
            </geometry>
            <material name="">
                <color rgba="0.1176 0.5059 0.6902 0.5" />
            </material>
        </visual>
        <collision>
            <origin rpy="0 0 0" xyz="0.435 0.75 0.65" />
            <geometry>
                <box size="0.87 1.5 1.3" />
            </geometry>
        </collision>
    </link>
    <joint name="kuka_fake_structure_left_foot" type="fixed">
        <origin rpy="0 0 0" xyz="2.45 -0.05  0" />
        <parent link="structure_base_link" />
        <child link="structure_fake_structure_left_foot" />
    </joint>
    <link name="structure_fake_structure_left_foot">
        <inertial>
            <origin rpy="0 0 0" xyz="0 0 00" />
            <mass value="10000" />
            <inertia ixx="0.1" ixy="0.0" ixz="0.0" iyy="0.1" iyz="0.0" izz="0.1" />
        </inertial>
        <visual>
            <origin rpy="0 0 0" xyz="0.435 0.75 0.65" />
            <geometry>
                <box size="0.87 1.5 1.3" />
            </geometry>
            <material name="">
                <color rgba="0.1176 0.5059 0.6902 0.5" />
            </material>
        </visual>
        <collision>
            <origin rpy="0 0 0" xyz="0.435 0.75 0.65" />
            <geometry>
                <box size="0.87 1.5 1.3" />
            </geometry>
        </collision>
    </link>
    <joint name="kuka_fake_structure" type="fixed">
        <origin rpy="0 0 0" xyz="-0.45 0.2  0" />
        <parent link="structure_base_link" />
        <child link="structure_fake_structure" />
    </joint>
    <link name="structure_fake_structure">
        <inertial>
            <origin rpy="0 0 0" xyz="0 0 00" />
            <mass value="10000" />
            <inertia ixx="0.1" ixy="0.0" ixz="0.0" iyy="0.1" iyz="0.0" izz="0.1" />
        </inertial>
        <visual>
            <origin rpy="0 0 0" xyz="2.15 0.75 2.0" />
            <geometry>
                <box size="4.3 1.5 4.0" />
            </geometry>
            <material name="">
                <color rgba="0.1176 0.5059 0.6902 0.5" />
            </material>
        </visual>
        <collision>
            <origin rpy="0 0 0" xyz="2.15 0.75 2.0" />
            <geometry>
                <box size="4.3 1.5 4.0" />
            </geometry>
        </collision>
    </link>
    <!-- end increased collisions -->
    <joint name="world_to_kuka" type="fixed">
        <origin rpy="0 0 0" xyz="0 0 0" />
        <parent link="world" />
        <child link="structure_base_link" />
    </joint>
    <link name="table_base_link">
        <inertial>
            <origin rpy="0 0 0" xyz="0 0 0" />
            <mass value="0.0001" />
            <inertia ixx="0.000001" ixy="0" ixz="0" iyy="0.000001" iyz="0" izz="0.000001" />
        </inertial>
        <!-- <visual>
          <origin
            xyz="0 0 ${(leg_height+table_thickness)/2}"
            rpy="0 0 0" />
          <geometry>
            <box size="${table_width+0.1} ${table_length+0.1} ${leg_height+table_thickness+0.1}"/>
          </geometry>
          <material
            name="">
            <color
              rgba="0.1176 0.5059 0.6902 0.5" />
          </material>
        </visual>
        <collision>
          <origin
            xyz="0 0 ${(leg_height+table_thickness)/2}"
            rpy="0 0 0" />
          <geometry>
            <box size="${table_width} ${table_length} ${leg_height+table_thickness}"/>
          </geometry>
        </collision> -->
    </link>
    <link name="table_leg1_link">
        <inertial>
            <origin rpy="0 0 0" xyz="0 0 0.47" />
            <mass value="9.573825" />
            <inertia ixx="0.707824795" ixy="0" ixz="0" iyy="0.707824795" iyz="0" izz="0.005744294999999999" />
        </inertial>
        <visual>
            <origin rpy="0 0 0" xyz="0 0 0.47" />
            <geometry>
                <box size="0.06 0.06 0.94" />
            </geometry>
            <material name="">
                <color rgba="0.1176 0.5059 0.6902 1" />
            </material>
        </visual>
        <collision>
            <origin rpy="0 0 0" xyz="0 0 0.47" />
            <geometry>
                <box size="0.06 0.06 0.94" />
            </geometry>
        </collision>
    </link>
    <joint name="table_base_to_leg1" type="fixed">
        <origin rpy="0 0 0" xyz="0.72 0.71 0" />
        <parent link="table_base_link" />
        <child link="table_leg1_link" />
    </joint>
    <link name="table_leg2_link">
        <inertial>
            <origin rpy="0 0 0" xyz="0 0 0.47" />
            <mass value="9.573825" />
            <inertia ixx="0.707824795" ixy="0" ixz="0" iyy="0.707824795" iyz="0" izz="0.005744294999999999" />
        </inertial>
        <visual>
            <origin rpy="0 0 0" xyz="0 0 0.47" />
            <geometry>
                <box size="0.06 0.06 0.94" />
            </geometry>
            <material name="">
                <color rgba="0.1176 0.5059 0.6902 1" />
            </material>
        </visual>
        <collision>
            <origin rpy="0 0 0" xyz="0 0 0.47" />
            <geometry>
                <box size="0.06 0.06 0.94" />
            </geometry>
        </collision>
    </link>
    <joint name="table_base_to_leg2" type="fixed">
        <origin rpy="0 0 0" xyz="0.72 -0.71 0" />
        <parent link="table_base_link" />
        <child link="table_leg2_link" />
    </joint>
    <link name="table_leg3_link">
        <inertial>
            <origin rpy="0 0 0" xyz="0 0 0.47" />
            <mass value="9.573825" />
            <inertia ixx="0.707824795" ixy="0" ixz="0" iyy="0.707824795" iyz="0" izz="0.005744294999999999" />
        </inertial>
        <visual>
            <origin rpy="0 0 0" xyz="0 0 0.47" />
            <geometry>
                <box size="0.06 0.06 0.94" />
            </geometry>
            <material name="">
                <color rgba="0.1176 0.5059 0.6902 1" />
            </material>
        </visual>
        <collision>
            <origin rpy="0 0 0" xyz="0 0 0.47" />
            <geometry>
                <box size="0.06 0.06 0.94" />
            </geometry>
        </collision>
    </link>
    <joint name="table_base_to_leg3" type="fixed">
        <origin rpy="0 0 0" xyz="-0.72 -0.71 0" />
        <parent link="table_base_link" />
        <child link="table_leg3_link" />
    </joint>
    <link name="table_leg4_link">
        <inertial>
            <origin rpy="0 0 0" xyz="0 0 0.47" />
            <mass value="9.573825" />
            <inertia ixx="0.707824795" ixy="0" ixz="0" iyy="0.707824795" iyz="0" izz="0.005744294999999999" />
        </inertial>
        <visual>
            <origin rpy="0 0 0" xyz="0 0 0.47" />
            <geometry>
                <box size="0.06 0.06 0.94" />
            </geometry>
            <material name="">
                <color rgba="0.1176 0.5059 0.6902 1" />
            </material>
        </visual>
        <collision>
            <origin rpy="0 0 0" xyz="0 0 0.47" />
            <geometry>
                <box size="0.06 0.06 0.94" />
            </geometry>
        </collision>
    </link>
    <joint name="table_base_to_leg4" type="fixed">
        <origin rpy="0 0 0" xyz="-0.72 0.71 0" />
        <parent link="table_base_link" />
        <child link="table_leg4_link" />
    </joint>
    <link name="table_tabletop_link">
        <inertial>
            <origin rpy="0 0 0" xyz="0 0 0.0075" />
            <mass value="9.573825" />
            <inertia ixx="47.774738203125" ixy="0" ixz="0" iyy="49.074538213124995" iyz="0" izz="96.83946249" />
        </inertial>
        <visual>
            <origin rpy="0 0 0" xyz="0 0 0.0075" />
            <geometry>
                <box size="1.5 1.48 0.015" />
            </geometry>
            <material name="">
                <color rgba="0.6608 0.6608 0.7878 1" />
            </material>
        </visual>
        <collision>
            <origin rpy="0 0 0" xyz="0 0 0.0075" />
            <geometry>
                <box size="1.5 1.48 0.015" />
            </geometry>
        </collision>
    </link>
    <joint name="table_base_to_tabletop" type="fixed">
        <origin rpy="0 0 0" xyz="0 0 0.94" />
        <parent link="table_base_link" />
        <child link="table_tabletop_link" />
    </joint>
    <link concave="yes" name="table_can_hole">
        <inertial>
            <origin rpy="0 0 0" xyz="0 0 0" />
            <mass value="0.0001" />
            <inertia ixx="0.00000001" ixy="0" ixz="0" iyy="0.00000001" iyz="0" izz="0.00000001" />
        </inertial>
        <visual concave="yes">
            <origin rpy="0 0 0" xyz="0 0 0" />
            <geometry>
                <mesh filename="package://battery_cell_description/meshes/Hole_60.STL" />
            </geometry>
            <material name="">
                <color rgba="0.6608 0.6608 0.7878 1" />
            </material>
        </visual>
        <collision concave="yes">
            <origin rpy="0 0 0" xyz="0 0 0" />
            <geometry>
                <mesh filename="package://battery_cell_description/meshes/Hole_60.STL" />
            </geometry>
        </collision>
    </link>
    <joint name="table_tabletop_to_hole" type="fixed">
        <origin rpy="0 0 0" xyz="0.65 0.35 0.015" />
        <parent link="table_tabletop_link" />
        <child link="table_can_hole" />
    </joint>
    <link name="table_fake_plane">
        <inertial>
            <origin rpy="0 0 0" xyz="0 0 0" />
            <mass value="0.0001" />
            <inertia ixx="0.000001" ixy="0" ixz="0" iyy="0.000001" iyz="0" izz="0.000001" />
        </inertial>
        <visual>
            <origin rpy="0 0 0" xyz="0 0 -0.01" />
            <geometry>
                <!-- <box size="10 10 0.02"/> -->
                <box size="10 10 0.03" />
            </geometry>
            <material name="">
                <color rgba="0.1176 0.5059 0.6902 0.5" />
            </material>
        </visual>
        <collision>
            <origin rpy="0 0 0" xyz="0 0 -0.01" />
            <geometry>
                <box size="10 10 0.02" />
            </geometry>
        </collision>
    </link>
    <joint name="table_base_to_plane" type="fixed">
        <origin rpy="0 0 0" xyz="0 0 0.955" />
        <parent link="table_base_link" />
        <child link="table_fake_plane" />
    </joint>
    <link name="table_fake_wall">
        <inertial>
            <origin rpy="0 0 0" xyz="0 0 0" />
            <mass value="0.0001" />
            <inertia ixx="0.000001" ixy="0" ixz="0" iyy="0.000001" iyz="0" izz="0.000001" />
        </inertial>
        <visual>
            <origin rpy="0 0 0" xyz="0 -0.01 1" />
            <geometry>
                <box size="3 0.02 2" />
            </geometry>
            <material name="">
                <color rgba="0.1176 0.5059 0.6902 0.5" />
            </material>
        </visual>
        <collision>
            <origin rpy="0 0 0" xyz="0 -0.01 1" />
            <geometry>
                <box size="3 0.02 2" />
            </geometry>
        </collision>
    </link>
    <joint name="table_base_to_wall" type="fixed">
        <origin rpy="0 0 0" xyz="0 -0.40 0.5" />
        <parent link="table_base_link" />
        <child link="table_fake_wall" />
    </joint>
    <link name="table_vertex0" />
    <link name="table_vertex1" />
    <link name="table_vertex2" />
    <link name="table_vertex3" />
    <link name="table_vertex4" />
    <joint name="table_vertex0" type="fixed">
        <origin rpy="0 0 0" xyz="0 0 0" />
        <parent link="table_tabletop_link" />
        <child link="table_vertex0" />
    </joint>
    <joint name="table_vertex1" type="fixed">
        <origin rpy="0 0 0" xyz="0.75 0.74 0" />
        <parent link="table_tabletop_link" />
        <child link="table_vertex1" />
    </joint>
    <joint name="table_vertex2" type="fixed">
        <origin rpy="0 0 0" xyz="0.75 -0.74 0" />
        <parent link="table_tabletop_link" />
        <child link="table_vertex2" />
    </joint>
    <joint name="table_vertex3" type="fixed">
        <origin rpy="0 0 0" xyz="-0.75 0.74 0" />
        <parent link="table_tabletop_link" />
        <child link="table_vertex3" />
    </joint>
    <joint name="table_vertex4" type="fixed">
        <origin rpy="0 0 0" xyz="-0.75 -0.74 0" />
        <parent link="table_tabletop_link" />
        <child link="table_vertex4" />
    </joint>
    <joint name="world_to_table" type="fixed">
        <origin rpy="0 0 -0.015" xyz="0.051 -1.61 0" />
        <parent link="world" />
        <child link="table_base_link" />
    </joint>
    <link name="comau_basement">
        <inertial>
            <origin rpy="0 0 0" xyz="0 0 00" />
            <mass value="10000" />
            <inertia ixx="0.1" ixy="0.0" ixz="0.0" iyy="0.1" iyz="0.0" izz="0.1" />
        </inertial>
        <visual>
            <origin rpy="0 0 0" xyz="0 0 0.014" />
            <geometry>
                <box size="1.11 1.01 0.028" />
            </geometry>
            <material name="">
                <color rgba="0.1176 0.5059 0.6902 1" />
            </material>
        </visual>
        <collision>
            <origin rpy="0 0 0" xyz="0.555 0.505 0.014" />
            <geometry>
                <box size="1.11 1.01 0.028" />
            </geometry>
        </collision>
    </link>
    <!-- <xacro:include filename="$(find nj_220_2_7_description)/urdf/nj_220_2_7.xacro" />
    <xacro:nj_220_2_7 prefix="${prefix}${nj_prefix}"/>

    <joint name="${prefix}${nj_prefix}basement_to_robot" type="fixed">
      <origin
        xyz="0 0 ${basement_lenght_z}"
        rpy="0 0 0" />
      <parent link="${prefix}${nj_prefix}basement"/>
      <child link="${prefix}${nj_prefix}base_link"/>
    </joint> -->
    <joint name="comau_fake_robot" type="fixed">
        <origin rpy="0 0 0" xyz="-0.05 -0.05 0.028" />
        <parent link="comau_basement" />
        <child link="comau_fake_robot" />
    </joint>
    <link name="comau_fake_robot">
        <inertial>
            <origin rpy="0 0 0" xyz="0 0 00" />
            <mass value="10000" />
            <inertia ixx="0.1" ixy="0.0" ixz="0.0" iyy="0.1" iyz="0.0" izz="0.1" />
        </inertial>
        <visual>
            <origin rpy="0 0 0" xyz="0 0 1.5" />
            <geometry>
                <box size="2 3 3" />
            </geometry>
            <material name="">
                <color rgba="0.1176 0.5059 0.6902 0.5" />
            </material>
        </visual>
        <collision>
            <origin rpy="0 0 0" xyz="0 0 1.5" />
            <geometry>
                <box size="2 3 3" />
            </geometry>
        </collision>
    </link>
    <!-- end increased collisions -->
    <joint name="world_to_comau" type="fixed">
        <origin rpy="0 0 3.14159" xyz="-2.708 -0.430 0" />
        <parent link="world" />
        <child link="comau_basement" />
    </joint>
    <transmission name="trans_gripper_left_joint">
        <type>transmission_interface/SimpleTransmission</type>
        <joint name="gripper_left_joint">
            <hardwareInterface>hardware_interface/EffortJointInterface</hardwareInterface>
        </joint>
        <actuator name="gripper_left_joint_motor">
            <hardwareInterface>hardware_interface/EffortJointInterface</hardwareInterface>
            <mechanicalReduction>1</mechanicalReduction>
        </actuator>
    </transmission>
    <transmission name="trans_gripper_right_joint">
        <type>transmission_interface/SimpleTransmission</type>
        <joint name="gripper_right_joint">
            <hardwareInterface>hardware_interface/EffortJointInterface</hardwareInterface>
        </joint>
        <actuator name="gripper_right_joint_motor">
            <hardwareInterface>hardware_interface/EffortJointInterface</hardwareInterface>
            <mechanicalReduction>1</mechanicalReduction>
        </actuator>
    </transmission>
    <transmission name="trans_gripper_middle_left_joint_circle">
        <type>transmission_interface/SimpleTransmission</type>
        <joint name="gripper_middle_left_joint_circle">
            <hardwareInterface>hardware_interface/EffortJointInterface</hardwareInterface>
        </joint>
        <actuator name="gripper_middle_left_joint_circle_motor">
            <hardwareInterface>hardware_interface/EffortJointInterface</hardwareInterface>
            <mechanicalReduction>1</mechanicalReduction>
        </actuator>
    </transmission>
    <transmission name="trans_gripper_end_left_joint_circle">
        <type>transmission_interface/SimpleTransmission</type>
        <joint name="gripper_end_left_joint_circle">
            <hardwareInterface>hardware_interface/EffortJointInterface</hardwareInterface>
        </joint>
        <actuator name="gripper_end_left_joint_circle_motor">
            <hardwareInterface>hardware_interface/EffortJointInterface</hardwareInterface>
            <mechanicalReduction>1</mechanicalReduction>
        </actuator>
    </transmission>
    <transmission name="trans_gripper_middle_right_joint_circle">
        <type>transmission_interface/SimpleTransmission</type>
        <joint name="gripper_middle_right_joint_circle">
            <hardwareInterface>hardware_interface/EffortJointInterface</hardwareInterface>
        </joint>
        <actuator name="gripper_middle_right_joint_circle_motor">
            <hardwareInterface>hardware_interface/EffortJointInterface</hardwareInterface>
            <mechanicalReduction>1</mechanicalReduction>
        </actuator>
    </transmission>
    <transmission name="trans_gripper_end_right_joint_circle">
        <type>transmission_interface/SimpleTransmission</type>
        <joint name="gripper_end_right_joint_circle">
            <hardwareInterface>hardware_interface/EffortJointInterface</hardwareInterface>
        </joint>
        <actuator name="gripper_end_right_joint_circle_motor">
            <hardwareInterface>hardware_interface/EffortJointInterface</hardwareInterface>
            <mechanicalReduction>1</mechanicalReduction>
        </actuator>
    </transmission>
    <gazebo>
        <plugin name="gazebo_ros_control">
            <robotNamespace>/</robotNamespace>
        </plugin>
    </gazebo>
</robot>

