<?xml version="1.0" ?>
<!-- =================================================================================== -->
<!-- |    This document was autogenerated by xacro from /home/abel/projects/personal_ws/src/battery_cell/battery_cell_description/urdf/battery_cell.xacro | -->
<!-- |    EDITING THIS FILE BY HAND IS NOT RECOMMENDED                                 | -->
<!-- =================================================================================== -->
<robot name="battery_cell">
    <link name="world" />
    <!--  100째/s -->
    <link name="structure_base_link">
        <inertial>
            <origin rpy="0 0 0" xyz="0.035817 -0.1978 -1.2121E-05" />
            <mass value="780.97" />
            <inertia ixx="25.789" ixy="-0.0076742" ixz="0.0023584" iyy="48.078" iyz="2.5193E-05" izz="33.648" />
        </inertial>
        <visual>
            <origin rpy="0 0 0" xyz="0 0 0" />
            <geometry>
                <mesh filename="package://kuka_structure_gazebo/meshes/base_link.STL" scale="0.001 0.001 0.001" />
            </geometry>
            <material name="">
                <color rgba="1 0 0 1" />
            </material>
        </visual>
        <collision>
            <origin rpy="0 0 0" xyz="0 0 0" />
            <geometry>
                <mesh filename="package://kuka_structure_gazebo/meshes/base_link.STL" scale="0.001 0.001 0.001" />
            </geometry>
        </collision>
    </link>
    <link name="structure_link_1">
        <inertial>
            <origin rpy="0 0 0" xyz="-0.28012 0.38938 0.024882" />
            <mass value="660.35" />
            <inertia ixx="38.274" ixy="9.9756" ixz="-0.5181" iyy="36.77" iyz="0.16531" izz="32.584" />
        </inertial>
        <visual>
            <origin rpy="0 0 0" xyz="0 0 0" />
            <geometry>
                <mesh filename="package://kuka_structure_gazebo/meshes/link_1.STL" scale="0.001 0.001 0.001" />
            </geometry>
            <material name="">
                <color rgba="1 0 0 1" />
            </material>
        </visual>
        <collision>
            <origin rpy="0 0 0" xyz="0 0 0" />
            <geometry>
                <mesh filename="package://kuka_structure_gazebo/meshes/link_1.STL" scale="0.001 0.001 0.001" />
            </geometry>
        </collision>
    </link>
    <joint name="structure_joint_1" type="prismatic">
        <origin rpy="0 0 0" xyz="2.750 0.215 2.720" />
        <parent link="structure_base_link" />
        <child link="structure_link_1" />
        <axis xyz="-1 0 0" />
        <limit effort="100000" lower="0" upper="3.0" velocity="1.74533" />
    </joint>
    <transmission name="structure_tran_1">
        <type>transmission_interface/SimpleTransmission</type>
        <joint name="structure_joint_1">
            <hardwareInterface>hardware_interface/PositionJointInterface</hardwareInterface>
        </joint>
        <actuator name="structure_motor_1">
            <mechanicalReduction>1</mechanicalReduction>
            <hardwareInterface>hardware_interface/EffortJointInterface</hardwareInterface>
        </actuator>
    </transmission>
    <gazebo>
        <plugin filename="libgazebo_ros_control.so" name="gazebo_ros_control">
            <robotNamespace>structure_/kuka_structure</robotNamespace>
            <robotSimType>gazebo_ros_control/DefaultRobotHWSim</robotSimType>
        </plugin>
    </gazebo>
    <gazebo reference="structure_base_link">
        <gravity>true</gravity>
        <selfCollide>false</selfCollide>
        <material>Gazebo/DarkGrey</material>
    </gazebo>
    <gazebo reference="structure_link_1">
        <gravity>true</gravity>
        <selfCollide>false</selfCollide>
        <material>Gazebo/Grey</material>
    </gazebo>
    <joint name="world_to_kuka_structure" type="fixed">
        <origin rpy="0 0 0" xyz="1 1 0" />
        <parent link="world" />
        <child link="structure_base_link" />
    </joint>
    <!-- -350째 -->
    <!--  360째/s -->
    <link name="kr_base_link">
        <inertial>
            <origin rpy="0 0 0" xyz="-0.080585 0.00067592 0.086754" />
            <mass value="30.385" />
            <inertia ixx="0.38941" ixy="0.0047083" ixz="0.060696" iyy="0.87424" iyz="-0.00029206" izz="1.0819" />
        </inertial>
        <visual>
            <origin rpy="0 0 0" xyz="0 0 0" />
            <geometry>
                <mesh filename="package://kr_50_r2500_description/meshes/base_link.STL" />
            </geometry>
            <material name="">
                <color rgba="0.79216 0.81961 0.93333 1" />
            </material>
        </visual>
        <collision>
            <origin rpy="0 0 0" xyz="0 0 0" />
            <geometry>
                <mesh filename="package://kr_50_r2500_description/meshes/base_link.STL" />
            </geometry>
        </collision>
    </link>
    <link name="kr_link1">
        <inertial>
            <origin rpy="0 0 0" xyz="0.0600446329714386 0.0116665626627102 0.247062352627269" />
            <mass value="56.0953515273858" />
            <inertia ixx="1.7123503270672" ixy="0.020886843872196" ixz="-0.525246219592262" iyy="2.15349859010488" iyz="-0.031415061955379" izz="1.31690706549715" />
        </inertial>
        <visual>
            <origin rpy="0 0 0" xyz="0 0 0" />
            <geometry>
                <mesh filename="package://kr_50_r2500_description/meshes/link1.STL" />
            </geometry>
            <material name="">
                <color rgba="0.792156862745098 0.819607843137255 0.933333333333333 1" />
            </material>
        </visual>
        <collision>
            <origin rpy="0 0 0" xyz="0 0 0" />
            <geometry>
                <mesh filename="package://kr_50_r2500_description/meshes/link1.STL" />
            </geometry>
        </collision>
    </link>
    <joint name="kr_joint1" type="revolute">
        <origin rpy="1.5708 0.009141 0" xyz="0 -0.17 0" />
        <parent link="kr_base_link" />
        <child link="kr_link1" />
        <axis xyz="0 0 -1" />
        <limit effort="10000" lower="-3.22886" upper="3.22886" velocity="3.05433" />
    </joint>
    <link name="kr_link2">
        <inertial>
            <origin rpy="0 0 0" xyz="0.0040251350126134 -0.177497207044946 0.578963319749875" />
            <mass value="35.5942562362571" />
            <inertia ixx="4.47662495992728" ixy="-0.00203441583192867" ixz="0.0769841500591921" iyy="4.49958249588231" iyz="0.214283202316168" izz="0.238618624180958" />
        </inertial>
        <visual>
            <origin rpy="0 0 0" xyz="0 0 0" />
            <geometry>
                <mesh filename="package://kr_50_r2500_description/meshes/link2.STL" />
            </geometry>
            <material name="">
                <color rgba="0.792156862745098 0.819607843137255 0.933333333333333 1" />
            </material>
        </visual>
        <collision>
            <origin rpy="0 0 0" xyz="0 0 0" />
            <geometry>
                <mesh filename="package://kr_50_r2500_description/meshes/link2.STL" />
            </geometry>
        </collision>
    </link>
    <joint name="kr_joint2" type="revolute">
        <origin rpy="0 1.557055  0" xyz="0.175 -0.074807 0.405" />
        <parent link="kr_link1" />
        <child link="kr_link2" />
        <axis xyz="0 1 0" />
        <limit effort="10000" lower="-3.05433" upper="1.0472" velocity="2.75762" />
    </joint>
    <link name="kr_link3">
        <inertial>
            <origin rpy="0 0 0" xyz="0.0305175734183824 0.097105360534718 0.0162382856824868" />
            <mass value="36.6784876951283" />
            <inertia ixx="0.563908772434098" ixy="0.0648382829251099" ixz="-0.0822356915818992" iyy="0.7868662787778" iyz="0.00379928707270628" izz="1.01511384262152" />
        </inertial>
        <visual>
            <origin rpy="0 0 0" xyz="0 0 0" />
            <geometry>
                <mesh filename="package://kr_50_r2500_description/meshes/link3.STL" />
            </geometry>
            <material name="">
                <color rgba="0.792156862745098 0.819607843137255 0.933333333333333 1" />
            </material>
        </visual>
        <collision>
            <origin rpy="0 0 0" xyz="0 0 0" />
            <geometry>
                <mesh filename="package://kr_50_r2500_description/meshes/link3.STL" />
            </geometry>
        </collision>
    </link>
    <joint name="kr_joint3" type="revolute">
        <origin rpy="0 -1.557055 0" xyz="0 0 1.29" />
        <parent link="kr_link2" />
        <child link="kr_link3" />
        <axis xyz="0 1 0" />
        <limit effort="10000" lower="-2.0944" upper="2.96706" velocity="3.05433" />
    </joint>
    <link name="kr_link4">
        <inertial>
            <origin rpy="0 0 0" xyz="0.400085577392824 0.0280533450779974 -6.01461215805621E-05" />
            <mass value="15.1542881051753" />
            <inertia ixx="0.0701060691297577" ixy="-0.0990093812478981" ixz="0.00018489912158269" iyy="0.729933929975417" iyz="-2.55452640777306E-05" izz="0.748398699396793" />
        </inertial>
        <visual>
            <origin rpy="0 0 0" xyz="0 0 0" />
            <geometry>
                <mesh filename="package://kr_50_r2500_description/meshes/link4.STL" />
            </geometry>
            <material name="">
                <color rgba="0.792156862745098 0.819607843137255 0.933333333333333 1" />
            </material>
        </visual>
        <collision>
            <origin rpy="0 0 0" xyz="0 0 0" />
            <geometry>
                <mesh filename="package://kr_50_r2500_description/meshes/link4.STL" />
            </geometry>
        </collision>
    </link>
    <joint name="kr_joint4" type="revolute">
        <origin rpy="0 0 0" xyz="0.32687 0.074807 0.05" />
        <parent link="kr_link3" />
        <child link="kr_link4" />
        <axis xyz="1 0 0" />
        <limit effort="10000" lower="-3.14159" upper="3.14159" velocity="4.36332" />
    </joint>
    <link name="kr_link5">
        <inertial>
            <origin rpy="0 0 0" xyz="0.0348166227286741 -0.0333672873060013 -7.86869120463773E-05" />
            <mass value="5.17490767884354" />
            <inertia ixx="0.0198943557123769" ixy="-0.00379528838423929" ixz="-3.17734786601442E-05" iyy="0.0325404927644558" iyz="2.0392665049925E-05" izz="0.0334468145607699" />
        </inertial>
        <visual>
            <origin rpy="0 0 0" xyz="0 0 0" />
            <geometry>
                <mesh filename="package://kr_50_r2500_description/meshes/link5.STL" />
            </geometry>
            <material name="">
                <color rgba="0.792156862745098 0.819607843137255 0.933333333333333 1" />
            </material>
        </visual>
        <collision>
            <origin rpy="0 0 0" xyz="0 0 0" />
            <geometry>
                <mesh filename="package://kr_50_r2500_description/meshes/link5.STL" />
            </geometry>
        </collision>
    </link>
    <joint name="kr_joint5" type="revolute">
        <origin rpy="0 -0.0 0" xyz="0.708131634616243 0 0" />
        <parent link="kr_link4" />
        <child link="kr_link5" />
        <axis xyz="0 1 0" />
        <limit effort="10000" lower="-2.18166" upper="2.18166" velocity="4.36332" />
    </joint>
    <link name="kr_link6">
        <inertial>
            <origin rpy="0 0 0" xyz="0.0697663509698883 -2.97159715269453E-06 -4.15148219581329E-05" />
            <mass value="0.362972835401582" />
            <inertia ixx="0.000809216081686161" ixy="9.97029573660496E-10" ixz="2.41841688721677E-07" iyy="0.000440777200154296" iyz="1.15745872636665E-07" izz="0.000441694717362902" />
        </inertial>
        <visual>
            <origin rpy="0 0 0" xyz="0 0 0" />
            <geometry>
                <mesh filename="package://kr_50_r2500_description/meshes/link6.STL" />
            </geometry>
            <material name="">
                <color rgba="0.792156862745098 0.819607843137255 0.933333333333333 1" />
            </material>
        </visual>
        <collision>
            <origin rpy="0 0 0" xyz="0 0 0" />
            <geometry>
                <mesh filename="package://kr_50_r2500_description/meshes/link6.STL" />
            </geometry>
        </collision>
    </link>
    <joint name="kr_joint6" type="revolute">
        <origin rpy="0 0 0" xyz="0.0966663727881543 0 0" />
        <parent link="kr_link5" />
        <child link="kr_link6" />
        <axis xyz="1 0 0" />
        <limit effort="10000" lower="-6.10865" upper="6.10865" velocity="6.28319" />
    </joint>
    <joint name="kr_link6_to_flange" type="fixed">
        <origin rpy="0 1.57079632679 0" xyz="0.07 0 0" />
        <parent link="kr_link6" />
        <child link="kr_flange" />
    </joint>
    <link name="kr_flange">
        <inertial>
            <origin rpy="0 0 0" xyz="0 0 0" />
            <mass value="0.01" />
            <inertia ixx="0.0001" ixy="0.0000" ixz="0.0000" iyy="0.0001" iyz="0.0000" izz="0.0001" />
        </inertial>
    </link>
    <transmission name="kr_tran1">
        <type>transmission_interface/SimpleTransmission</type>
        <joint name="kr_joint1">
            <hardwareInterface>hardware_interface/EffortJointInterface</hardwareInterface>
        </joint>
        <actuator name="kr_motor1">
            <mechanicalReduction>1</mechanicalReduction>
            <hardwareInterface>hardware_interface/EffortJointInterface</hardwareInterface>
        </actuator>
    </transmission>
    <transmission name="kr_tran2">
        <type>transmission_interface/SimpleTransmission</type>
        <joint name="kr_joint2">
            <hardwareInterface>hardware_interface/EffortJointInterface</hardwareInterface>
        </joint>
        <actuator name="kr_motor2">
            <mechanicalReduction>1</mechanicalReduction>
            <hardwareInterface>hardware_interface/EffortJointInterface</hardwareInterface>
        </actuator>
    </transmission>
    <transmission name="kr_tran3">
        <type>transmission_interface/SimpleTransmission</type>
        <joint name="kr_joint3">
            <hardwareInterface>hardware_interface/EffortJointInterface</hardwareInterface>
        </joint>
        <actuator name="kr_motor3">
            <mechanicalReduction>1</mechanicalReduction>
            <hardwareInterface>hardware_interface/EffortJointInterface</hardwareInterface>
        </actuator>
    </transmission>
    <transmission name="kr_tran4">
        <type>transmission_interface/SimpleTransmission</type>
        <joint name="kr_joint4">
            <hardwareInterface>hardware_interface/EffortJointInterface</hardwareInterface>
        </joint>
        <actuator name="kr_motor4">
            <mechanicalReduction>1</mechanicalReduction>
            <hardwareInterface>hardware_interface/EffortJointInterface</hardwareInterface>
        </actuator>
    </transmission>
    <transmission name="kr_tran5">
        <type>transmission_interface/SimpleTransmission</type>
        <joint name="kr_joint5">
            <hardwareInterface>hardware_interface/EffortJointInterface</hardwareInterface>
        </joint>
        <actuator name="kr_motor5">
            <mechanicalReduction>1</mechanicalReduction>
            <hardwareInterface>hardware_interface/EffortJointInterface</hardwareInterface>
        </actuator>
    </transmission>
    <transmission name="kr_tran6">
        <type>transmission_interface/SimpleTransmission</type>
        <joint name="kr_joint6">
            <hardwareInterface>hardware_interface/EffortJointInterface</hardwareInterface>
        </joint>
        <actuator name="kr_motor6">
            <mechanicalReduction>1</mechanicalReduction>
            <hardwareInterface>hardware_interface/EffortJointInterface</hardwareInterface>
        </actuator>
    </transmission>
    <joint name="kuka_structure_to_kr_50_r2500" type="fixed">
        <origin rpy="0 1.5707963267948966 0" xyz="0.333 -0.035 0.325" />
        <parent link="structure_link_1" />
        <child link="kr_base_link" />
    </joint>
    <link name="kr_gripper_base">
        <inertial>
            <origin rpy="0 0 0" xyz="0 0 0" />
            <mass value="0.2" />
            <inertia ixx="0.001" ixy="0.0" ixz="0.0" iyy="0.001" iyz="0.0" izz="0.001" />
        </inertial>
        <visual>
            <origin rpy="0 0 0" xyz="0 0 0.025" />
            <geometry>
                <box size="0.1 0.05 0.05" />
            </geometry>
            <material name="aluminium">
                <color rgba="0.515625 0.52734375 0.53515625 1" />
            </material>
        </visual>
        <collision>
            <origin rpy="0 0 0" xyz="0 0 0.025" />
            <geometry>
                <box size="0.1 0.05 0.05" />
            </geometry>
            <material name="aluminium">
                <color rgba="0.515625 0.52734375 0.53515625 1" />
            </material>
        </collision>
    </link>
    <!-- <xacro:if value="${contact}"> -->
    <contact>
        <friction_anchor />
        <stiffness value="" />
        <damping value="" />
        <spinning_friction value="" />
        <lateral_friction value="" />
    </contact>
    <!-- </xacro:if> -->
    <link name="kr_open_tip" />
    <joint name="kr_open_tip_joint" type="fixed">
        <origin rpy="0 0 0" xyz="0 0 0.13782116141076978" />
        <parent link="kr_gripper_base" />
        <child link="kr_open_tip" />
    </joint>
    <link name="kr_closed_tip" />
    <joint name="kr_closed_tip_joint" type="fixed">
        <origin rpy="0 0 0" xyz="0 0 0.14898979485566355" />
        <parent link="kr_gripper_base" />
        <child link="kr_closed_tip" />
    </joint>
    <link name="kr_zero_pos_tip" />
    <joint name="kr_zero_pos_tip_joint" type="fixed">
        <origin rpy="0 0 0" xyz="0 0 0.17" />
        <parent link="kr_gripper_base" />
        <child link="kr_zero_pos_tip" />
    </joint>
    <!-- <xacro:property name="contact" value='true' />
    <xacro:property name="stiffness" value="30000.0" />
    <xacro:property name="damping" value="1000.0" />
    <xacro:property name="spinning_friction" value="0.1" />
    <xacro:property name="lateral_friction" value="1.0" /> -->
    <link name="kr_right_crank">
        <inertial>
            <origin rpy="0 0 0" xyz="0 0 0" />
            <mass value="0.2" />
            <inertia ixx="0.001" ixy="0.0" ixz="0.0" iyy="0.001" iyz="0.0" izz="0.001" />
        </inertial>
        <visual>
            <origin rpy="0 0 0" xyz="0 0 0.035" />
            <geometry>
                <box size="0.01 0.05 0.07" />
            </geometry>
            <material name="aluminium">
                <color rgba="0.515625 0.52734375 0.53515625 1" />
            </material>
        </visual>
        <collision>
            <origin rpy="0 0 0" xyz="0 0 0.035" />
            <geometry>
                <box size="0.01 0.05 0.07" />
            </geometry>
            <material name="aluminium">
                <color rgba="0.515625 0.52734375 0.53515625 1" />
            </material>
        </collision>
    </link>
    <!-- <xacro:if value="${contact}"> -->
    <contact>
        <friction_anchor />
        <stiffness value="" />
        <damping value="" />
        <spinning_friction value="" />
        <lateral_friction value="" />
    </contact>
    <!-- </xacro:if> -->
    <link name="kr_right_external_crank">
        <inertial>
            <origin rpy="0 0 0" xyz="0 0 0" />
            <mass value="0.2" />
            <inertia ixx="0.001" ixy="0.0" ixz="0.0" iyy="0.001" iyz="0.0" izz="0.001" />
        </inertial>
        <visual>
            <origin rpy="0 0 0" xyz="0 0 0.035" />
            <geometry>
                <box size="0.01 0.05 0.07" />
            </geometry>
            <material name="aluminium">
                <color rgba="0.515625 0.52734375 0.53515625 1" />
            </material>
        </visual>
        <collision>
            <origin rpy="0 0 0" xyz="0 0 0.035" />
            <geometry>
                <box size="0.01 0.05 0.07" />
            </geometry>
            <material name="aluminium">
                <color rgba="0.515625 0.52734375 0.53515625 1" />
            </material>
        </collision>
    </link>
    <!-- <xacro:if value="${contact}"> -->
    <contact>
        <friction_anchor />
        <stiffness value="" />
        <damping value="" />
        <spinning_friction value="" />
        <lateral_friction value="" />
    </contact>
    <!-- </xacro:if> -->
    <link name="kr_right_rod">
        <inertial>
            <origin rpy="0 0 0" xyz="0 0 0" />
            <mass value="0.2" />
            <inertia ixx="0.001" ixy="0.0" ixz="0.0" iyy="0.001" iyz="0.0" izz="0.001" />
        </inertial>
        <visual>
            <origin rpy="0 0 0" xyz="0 0 0.025" />
            <geometry>
                <box size="0.01 0.05 0.05" />
            </geometry>
            <material name="aluminium">
                <color rgba="0.515625 0.52734375 0.53515625 1" />
            </material>
        </visual>
        <collision>
            <origin rpy="0 0 0" xyz="0 0 0.025" />
            <geometry>
                <box size="0.01 0.05 0.05" />
            </geometry>
            <material name="aluminium">
                <color rgba="0.515625 0.52734375 0.53515625 1" />
            </material>
        </collision>
    </link>
    <!-- <xacro:if value="${contact}"> -->
    <contact>
        <friction_anchor />
        <stiffness value="" />
        <damping value="" />
        <spinning_friction value="" />
        <lateral_friction value="" />
    </contact>
    <!-- </xacro:if> -->
    <link name="kr_right_base_rod">
        <inertial>
            <origin rpy="0 0 0" xyz="0 0 0" />
            <mass value="0.2" />
            <inertia ixx="0.001" ixy="0.0" ixz="0.0" iyy="0.001" iyz="0.0" izz="0.001" />
        </inertial>
        <visual>
            <origin rpy="0 0 0" xyz="0 0 0.025" />
            <geometry>
                <box size="0.01 0.05 0.05" />
            </geometry>
            <material name="aluminium">
                <color rgba="0.515625 0.52734375 0.53515625 1" />
            </material>
        </visual>
        <collision>
            <origin rpy="0 0 0" xyz="0 0 0.025" />
            <geometry>
                <box size="0.01 0.05 0.05" />
            </geometry>
            <material name="aluminium">
                <color rgba="0.515625 0.52734375 0.53515625 1" />
            </material>
        </collision>
    </link>
    <!-- <xacro:if value="${contact}"> -->
    <contact>
        <friction_anchor />
        <stiffness value="" />
        <damping value="" />
        <spinning_friction value="" />
        <lateral_friction value="" />
    </contact>
    <!-- </xacro:if> -->
    <link name="kr_right_phalanx">
        <inertial>
            <origin rpy="0 0 0" xyz="0 0 0" />
            <mass value="0.2" />
            <inertia ixx="0.001" ixy="0.0" ixz="0.0" iyy="0.001" iyz="0.0" izz="0.001" />
        </inertial>
        <visual>
            <origin rpy="0 0 0" xyz="0 0 0.025" />
            <geometry>
                <box size="0.01 0.05 0.05" />
            </geometry>
            <material name="aluminium">
                <color rgba="0.515625 0.52734375 0.53515625 1" />
            </material>
        </visual>
        <collision>
            <origin rpy="0 0 0" xyz="0 0 0.025" />
            <geometry>
                <box size="0.01 0.05 0.05" />
            </geometry>
            <material name="aluminium">
                <color rgba="0.515625 0.52734375 0.53515625 1" />
            </material>
        </collision>
    </link>
    <!-- <xacro:if value="${contact}"> -->
    <contact>
        <friction_anchor />
        <stiffness value="" />
        <damping value="" />
        <spinning_friction value="" />
        <lateral_friction value="" />
    </contact>
    <!-- </xacro:if> -->
    <!-- <xacro:box name="${prefix}phalanx" width="${link_width}" height="${link_height}" length="${phalanx_length}"
               contact="${contact}" stiffness="${stiffness}" damping="${damping}" spinning_friction="${spinning_friction}" lateral_friction="${lateral_friction}"/> -->
    <joint name="kr_right_finger_joint" type="revolute">
        <origin rpy="0 0 0" xyz="0.055 0 0.05" />
        <parent link="kr_gripper_base" />
        <child link="kr_right_crank" />
        <axis xyz="0 1 0" />
        <limit effort="5" lower="-0.7956029534845354" upper="1" velocity="5.0" />
    </joint>
    <joint name="kr_right_joint_2_5" type="fixed">
        <origin rpy="0 -1.5707963267948966 0" xyz="0 0 0" />
        <parent link="kr_right_rod" />
        <child link="kr_right_phalanx" />
        <axis xyz="0 1 0" />
    </joint>
    <joint name="kr_right_joint_1_2" type="revolute">
        <origin rpy="0 1.5707963267948966 0" xyz="0 0 0.07" />
        <parent link="kr_right_crank" />
        <child link="kr_right_rod" />
        <axis xyz="0 1 0" />
        <limit effort="10" lower="-3.141592653589793" upper="3.141592653589793" velocity="2.0" />
        <mimic joint="kr_right_finger_joint" multiplier="-1" offset="0" />
    </joint>
    <joint name="kr_right_joint_2_3" type="revolute">
        <origin rpy="0 1.5707963267948966 0" xyz="0 0 0.05" />
        <parent link="kr_right_rod" />
        <child link="kr_right_external_crank" />
        <axis xyz="0 1 0" />
        <limit effort="10" lower="-3.141592653589793" upper="3.141592653589793" velocity="2.0" />
        <mimic joint="kr_right_finger_joint" multiplier="1" offset="0" />
    </joint>
    <joint name="kr_right_joint_3_4" type="revolute">
        <origin rpy="0 1.5707963267948966 0" xyz="0 0 0.07" />
        <parent link="kr_right_external_crank" />
        <child link="kr_right_base_rod" />
        <axis xyz="0 1 0" />
        <limit effort="10" lower="-3.141592653589793" upper="3.141592653589793" velocity="2.0" />
        <mimic joint="kr_right_finger_joint" multiplier="-1" offset="0" />
    </joint>
    <!-- Add if to include this link only for rviz  -->
    <!-- <link name="${prefix}tip"/>
    <joint name="${prefix}tip_joint" type="fixed">
      <origin xyz="${-0.5*link_width} 0 ${phalanx_length}" rpy="0 0 0"/>
      <parent link="${prefix}phalanx" />
      <child link="${prefix}tip" />
    </joint> -->
    <!-- <gazebo>
      <joint name="${prefix}joint_4_1" type="revolute">
        <parent>${prefix}base_rod</parent>
        <child>${prefix}crank</child>
        <pose relative_to="${prefix}base_rod">0 0 ${rod_length}   0 ${pi/2} 0</pose>
        <axis>
          <xyz>0 1 0</xyz>
        </axis>
      </joint>

      <joint name="${prefix}joint_0_4" type="revolute">
        <parent>${base_name}</parent>
        <child>${prefix}base_rod</child>
        <pose relative_to="${base_name}">${(0.5*(base_x+link_width)+rod_length)*cos(rot_z)} 0 ${base_z} 0 0 ${rot_z}</pose>
        <axis>
          <xyz>0 1 0</xyz>
        </axis>
      </joint>
    </gazebo>

    <gazebo reference="${prefix}phalanx">
      <self_collide>1</self_collide>
      <kp>100000</kp>
      <kd>200</kd>
      <mu1>2</mu1>
      <mu2>2</mu2>
    </gazebo> -->
    <!-- <xacro:property name="contact" value='true' />
    <xacro:property name="stiffness" value="30000.0" />
    <xacro:property name="damping" value="1000.0" />
    <xacro:property name="spinning_friction" value="0.1" />
    <xacro:property name="lateral_friction" value="1.0" /> -->
    <link name="kr_left_crank">
        <inertial>
            <origin rpy="0 0 0" xyz="0 0 0" />
            <mass value="0.2" />
            <inertia ixx="0.001" ixy="0.0" ixz="0.0" iyy="0.001" iyz="0.0" izz="0.001" />
        </inertial>
        <visual>
            <origin rpy="0 0 0" xyz="0 0 0.035" />
            <geometry>
                <box size="0.01 0.05 0.07" />
            </geometry>
            <material name="aluminium">
                <color rgba="0.515625 0.52734375 0.53515625 1" />
            </material>
        </visual>
        <collision>
            <origin rpy="0 0 0" xyz="0 0 0.035" />
            <geometry>
                <box size="0.01 0.05 0.07" />
            </geometry>
            <material name="aluminium">
                <color rgba="0.515625 0.52734375 0.53515625 1" />
            </material>
        </collision>
    </link>
    <!-- <xacro:if value="${contact}"> -->
    <contact>
        <friction_anchor />
        <stiffness value="" />
        <damping value="" />
        <spinning_friction value="" />
        <lateral_friction value="" />
    </contact>
    <!-- </xacro:if> -->
    <link name="kr_left_external_crank">
        <inertial>
            <origin rpy="0 0 0" xyz="0 0 0" />
            <mass value="0.2" />
            <inertia ixx="0.001" ixy="0.0" ixz="0.0" iyy="0.001" iyz="0.0" izz="0.001" />
        </inertial>
        <visual>
            <origin rpy="0 0 0" xyz="0 0 0.035" />
            <geometry>
                <box size="0.01 0.05 0.07" />
            </geometry>
            <material name="aluminium">
                <color rgba="0.515625 0.52734375 0.53515625 1" />
            </material>
        </visual>
        <collision>
            <origin rpy="0 0 0" xyz="0 0 0.035" />
            <geometry>
                <box size="0.01 0.05 0.07" />
            </geometry>
            <material name="aluminium">
                <color rgba="0.515625 0.52734375 0.53515625 1" />
            </material>
        </collision>
    </link>
    <!-- <xacro:if value="${contact}"> -->
    <contact>
        <friction_anchor />
        <stiffness value="" />
        <damping value="" />
        <spinning_friction value="" />
        <lateral_friction value="" />
    </contact>
    <!-- </xacro:if> -->
    <link name="kr_left_rod">
        <inertial>
            <origin rpy="0 0 0" xyz="0 0 0" />
            <mass value="0.2" />
            <inertia ixx="0.001" ixy="0.0" ixz="0.0" iyy="0.001" iyz="0.0" izz="0.001" />
        </inertial>
        <visual>
            <origin rpy="0 0 0" xyz="0 0 0.025" />
            <geometry>
                <box size="0.01 0.05 0.05" />
            </geometry>
            <material name="aluminium">
                <color rgba="0.515625 0.52734375 0.53515625 1" />
            </material>
        </visual>
        <collision>
            <origin rpy="0 0 0" xyz="0 0 0.025" />
            <geometry>
                <box size="0.01 0.05 0.05" />
            </geometry>
            <material name="aluminium">
                <color rgba="0.515625 0.52734375 0.53515625 1" />
            </material>
        </collision>
    </link>
    <!-- <xacro:if value="${contact}"> -->
    <contact>
        <friction_anchor />
        <stiffness value="" />
        <damping value="" />
        <spinning_friction value="" />
        <lateral_friction value="" />
    </contact>
    <!-- </xacro:if> -->
    <link name="kr_left_base_rod">
        <inertial>
            <origin rpy="0 0 0" xyz="0 0 0" />
            <mass value="0.2" />
            <inertia ixx="0.001" ixy="0.0" ixz="0.0" iyy="0.001" iyz="0.0" izz="0.001" />
        </inertial>
        <visual>
            <origin rpy="0 0 0" xyz="0 0 0.025" />
            <geometry>
                <box size="0.01 0.05 0.05" />
            </geometry>
            <material name="aluminium">
                <color rgba="0.515625 0.52734375 0.53515625 1" />
            </material>
        </visual>
        <collision>
            <origin rpy="0 0 0" xyz="0 0 0.025" />
            <geometry>
                <box size="0.01 0.05 0.05" />
            </geometry>
            <material name="aluminium">
                <color rgba="0.515625 0.52734375 0.53515625 1" />
            </material>
        </collision>
    </link>
    <!-- <xacro:if value="${contact}"> -->
    <contact>
        <friction_anchor />
        <stiffness value="" />
        <damping value="" />
        <spinning_friction value="" />
        <lateral_friction value="" />
    </contact>
    <!-- </xacro:if> -->
    <link name="kr_left_phalanx">
        <inertial>
            <origin rpy="0 0 0" xyz="0 0 0" />
            <mass value="0.2" />
            <inertia ixx="0.001" ixy="0.0" ixz="0.0" iyy="0.001" iyz="0.0" izz="0.001" />
        </inertial>
        <visual>
            <origin rpy="0 0 0" xyz="0 0 0.025" />
            <geometry>
                <box size="0.01 0.05 0.05" />
            </geometry>
            <material name="aluminium">
                <color rgba="0.515625 0.52734375 0.53515625 1" />
            </material>
        </visual>
        <collision>
            <origin rpy="0 0 0" xyz="0 0 0.025" />
            <geometry>
                <box size="0.01 0.05 0.05" />
            </geometry>
            <material name="aluminium">
                <color rgba="0.515625 0.52734375 0.53515625 1" />
            </material>
        </collision>
    </link>
    <!-- <xacro:if value="${contact}"> -->
    <contact>
        <friction_anchor />
        <stiffness value="" />
        <damping value="" />
        <spinning_friction value="" />
        <lateral_friction value="" />
    </contact>
    <!-- </xacro:if> -->
    <!-- <xacro:box name="${prefix}phalanx" width="${link_width}" height="${link_height}" length="${phalanx_length}"
               contact="${contact}" stiffness="${stiffness}" damping="${damping}" spinning_friction="${spinning_friction}" lateral_friction="${lateral_friction}"/> -->
    <joint name="kr_left_finger_joint" type="revolute">
        <origin rpy="0 0 3.141592653589793" xyz="-0.055 0 0.05" />
        <parent link="kr_gripper_base" />
        <child link="kr_left_crank" />
        <axis xyz="0 1 0" />
        <limit effort="5" lower="-0.7956029534845354" upper="1" velocity="5.0" />
        <mimic joint="kr_right_finger_joint" multiplier="1" offset="0" />
    </joint>
    <joint name="kr_left_joint_2_5" type="fixed">
        <origin rpy="0 -1.5707963267948966 0" xyz="0 0 0" />
        <parent link="kr_left_rod" />
        <child link="kr_left_phalanx" />
        <axis xyz="0 1 0" />
    </joint>
    <joint name="kr_left_joint_1_2" type="revolute">
        <origin rpy="0 1.5707963267948966 0" xyz="0 0 0.07" />
        <parent link="kr_left_crank" />
        <child link="kr_left_rod" />
        <axis xyz="0 1 0" />
        <limit effort="10" lower="-3.141592653589793" upper="3.141592653589793" velocity="2.0" />
        <mimic joint="kr_left_finger_joint" multiplier="-1" offset="0" />
    </joint>
    <joint name="kr_left_joint_2_3" type="revolute">
        <origin rpy="0 1.5707963267948966 0" xyz="0 0 0.05" />
        <parent link="kr_left_rod" />
        <child link="kr_left_external_crank" />
        <axis xyz="0 1 0" />
        <limit effort="10" lower="-3.141592653589793" upper="3.141592653589793" velocity="2.0" />
        <mimic joint="kr_left_finger_joint" multiplier="1" offset="0" />
    </joint>
    <joint name="kr_left_joint_3_4" type="revolute">
        <origin rpy="0 1.5707963267948966 0" xyz="0 0 0.07" />
        <parent link="kr_left_external_crank" />
        <child link="kr_left_base_rod" />
        <axis xyz="0 1 0" />
        <limit effort="10" lower="-3.141592653589793" upper="3.141592653589793" velocity="2.0" />
        <mimic joint="kr_left_finger_joint" multiplier="-1" offset="0" />
    </joint>
    <!-- Add if to include this link only for rviz  -->
    <!-- <link name="${prefix}tip"/>
    <joint name="${prefix}tip_joint" type="fixed">
      <origin xyz="${-0.5*link_width} 0 ${phalanx_length}" rpy="0 0 0"/>
      <parent link="${prefix}phalanx" />
      <child link="${prefix}tip" />
    </joint> -->
    <!-- <gazebo>
      <joint name="${prefix}joint_4_1" type="revolute">
        <parent>${prefix}base_rod</parent>
        <child>${prefix}crank</child>
        <pose relative_to="${prefix}base_rod">0 0 ${rod_length}   0 ${pi/2} 0</pose>
        <axis>
          <xyz>0 1 0</xyz>
        </axis>
      </joint>

      <joint name="${prefix}joint_0_4" type="revolute">
        <parent>${base_name}</parent>
        <child>${prefix}base_rod</child>
        <pose relative_to="${base_name}">${(0.5*(base_x+link_width)+rod_length)*cos(rot_z)} 0 ${base_z} 0 0 ${rot_z}</pose>
        <axis>
          <xyz>0 1 0</xyz>
        </axis>
      </joint>
    </gazebo>

    <gazebo reference="${prefix}phalanx">
      <self_collide>1</self_collide>
      <kp>100000</kp>
      <kd>200</kd>
      <mu1>2</mu1>
      <mu2>2</mu2>
    </gazebo> -->
    <transmission name="kr_right_finger_joint_trans">
        <type>transmission_interface/SimpleTransmission</type>
        <joint name="kr_right_finger_joint">
            <hardwareInterface>hardware_interface/EffortJointInterface</hardwareInterface>
        </joint>
        <actuator name="kr_right_finger_joint_motor">
            <mechanicalReduction>1</mechanicalReduction>
            <hardwareInterface>hardware_interface/EffortJointInterface</hardwareInterface>
        </actuator>
    </transmission>
    <transmission name="kr_left_finger_joint_trans">
        <type>transmission_interface/SimpleTransmission</type>
        <joint name="kr_left_finger_joint">
            <hardwareInterface>hardware_interface/EffortJointInterface</hardwareInterface>
        </joint>
        <actuator name="kr_left_finger_joint_motor">
            <mechanicalReduction>1</mechanicalReduction>
            <hardwareInterface>hardware_interface/EffortJointInterface</hardwareInterface>
        </actuator>
    </transmission>
    <joint name="kr_gripper_joint" type="fixed">
        <origin rpy="0 0 0" xyz="0 0 0.018" />
        <parent link="kr_flange" />
        <child link="kr_gripper_base" />
    </joint>
    <!--  195째/s -->
    <link name="nj_base_link">
        <inertial>
            <origin rpy="0 0 0" xyz="0.035817 -0.00001 0.13320" />
            <mass value="780.97" />
            <inertia ixx="39.64573032" ixy="0.00269524" ixz="-3.73357627" iyy="48.50586929" iyz="-0.00127807" izz="49.079656" />
        </inertial>
        <visual>
            <origin rpy="0 0 0" xyz="0 0 0" />
            <geometry>
                <mesh filename="package://nj_220_2_7_description/meshes/base_link.STL" />
            </geometry>
            <material name="">
                <color rgba="1 0 0 1" />
            </material>
        </visual>
        <collision>
            <origin rpy="0 0 0" xyz="0 0 0" />
            <geometry>
                <mesh filename="package://nj_220_2_7_description/meshes/base_link.STL" />
            </geometry>
        </collision>
    </link>
    <link name="nj_link_1">
        <inertial>
            <origin rpy="0 0 0" xyz="0.31397 0.02536 0.37802" />
            <mass value="120.57" />
            <inertia ixx="96.14944607" ixy="2.82831578" ixz="59.92048931" iyy="132.52767347" iyz="3.87136939" izz="76.40305744" />
        </inertial>
        <visual>
            <origin rpy="0 0 0" xyz="0 0 0" />
            <geometry>
                <mesh filename="package://nj_220_2_7_description/meshes/link_1.STL" />
            </geometry>
            <material name="">
                <color rgba="1 0 0 1" />
            </material>
        </visual>
        <collision>
            <origin rpy="0 0 0" xyz="0 0 0" />
            <geometry>
                <mesh filename="package://nj_220_2_7_description/meshes/link_1.STL" />
            </geometry>
        </collision>
    </link>
    <joint name="nj_joint_1" type="revolute">
        <origin rpy="0 0 0" xyz="0 0 0.331" />
        <parent link="nj_base_link" />
        <child link="nj_link_1" />
        <axis xyz="0 0 1" />
        <limit effort="100000" lower="-1.570796327" upper="1.570796327" velocity="1.74533" />
    </joint>
    <link name="nj_link_2">
        <inertial>
            <origin rpy="0 0 0" xyz="0.018416 -0.00326 0.51384" />
            <mass value="120.34" />
            <inertia ixx="53.73638778" ixy="-0.00887173" ixz="1.24711967" iyy="53.48705119" iyz="-0.66793611" izz="2.25971599" />
        </inertial>
        <visual>
            <origin rpy="0 0 0" xyz="0 0 0" />
            <geometry>
                <mesh filename="package://nj_220_2_7_description/meshes/link_2.STL" />
            </geometry>
            <material name="">
                <color rgba="1 0 0 1" />
            </material>
        </visual>
        <collision>
            <origin rpy="0 0 0" xyz="0 0 0" />
            <geometry>
                <mesh filename="package://nj_220_2_7_description/meshes/link_2.STL" />
            </geometry>
        </collision>
    </link>
    <joint name="nj_joint_2" type="revolute">
        <origin rpy="0 0 0" xyz="0.4 0 0.499" />
        <parent link="nj_link_1" />
        <child link="nj_link_2" />
        <axis xyz="0 1 0" />
        <limit effort="100000" lower="-1.308996939" upper="1.658062789" velocity="1.5708" />
    </joint>
    <link name="nj_link_3">
        <inertial>
            <origin rpy="0 0 0" xyz="-0.04239 0.01939 0.2104" />
            <mass value="303.81" />
            <inertia ixx="24.45402173" ixy="-0.58037596" ixz="-2.46563321" iyy="20.71802091" iyz="2.40454026" izz="9.01610712" />
        </inertial>
        <visual>
            <origin rpy="0 0 0" xyz="0 0 0" />
            <geometry>
                <mesh filename="package://nj_220_2_7_description/meshes/link_3.STL" />
            </geometry>
            <material name="">
                <color rgba="1 0 0 1" />
            </material>
        </visual>
        <collision>
            <origin rpy="0 0 0" xyz="0 0 0" />
            <geometry>
                <mesh filename="package://nj_220_2_7_description/meshes/link_3.STL" />
            </geometry>
        </collision>
    </link>
    <link name="nj_link_3_virtual">
        <inertial>
            <origin rpy="0 0 0" xyz="0 0 0" />
            <mass value="0.01" />
            <inertia ixx="0.00001" ixy="0.00000" ixz="0.00000" iyy="0.00001" iyz="0.00000" izz="0.00000" />
        </inertial>
    </link>
    <joint name="nj_joint_2m" type="revolute">
        <origin rpy="0 0 0" xyz="0 0 1.175" />
        <parent link="nj_link_2" />
        <child link="nj_link_3_virtual" />
        <axis xyz="0 1 0" />
        <mimic joint="nj_joint_2" multiplier="-1" offset="0" />
        <limit effort="100000" lower="-6.2831853" upper="6.2831853" velocity="3.40339" />
    </joint>
    <joint name="nj_joint_3" type="revolute">
        <origin rpy="0 0 0" xyz="0 0 0" />
        <parent link="nj_link_3_virtual" />
        <child link="nj_link_3" />
        <axis xyz="0 -1 0" />
        <limit effort="100000" lower="-4.468042885" upper="0.174532925" velocity="1.91986" />
    </joint>
    <link name="nj_link_4">
        <inertial>
            <origin rpy="0 0 0" xyz="0.71228 -0.02567 -0.00003" />
            <mass value="90.963" />
            <inertia ixx="0.68929228290" ixy="-2.39235486446" ixz="-0.00192589885" iyy="58.11987131958" iyz="-0.00017654018" izz="58.29818388998" />
        </inertial>
        <visual>
            <origin rpy="0 0 0" xyz="0 0 0" />
            <geometry>
                <mesh filename="package://nj_220_2_7_description/meshes/link_4.STL" />
            </geometry>
            <material name="">
                <color rgba="1 0 0 1" />
            </material>
        </visual>
        <collision>
            <origin rpy="0 0 0" xyz="0 0 0" />
            <geometry>
                <mesh filename="package://nj_220_2_7_description/meshes/link_4.STL" />
            </geometry>
        </collision>
    </link>
    <joint name="nj_joint_4" type="revolute">
        <origin rpy="0 0 0" xyz="0.105 0 0.25" />
        <parent link="nj_link_3" />
        <child link="nj_link_4" />
        <axis xyz="1 0 0" />
        <limit effort="1230" lower="-6.2831853" upper="6.2831853" velocity="2.26893" />
    </joint>
    <link name="nj_link_5">
        <inertial>
            <origin rpy="0 0 0" xyz="0.09375 0.01506 0.00002" />
            <mass value="50.615" />
            <inertia ixx="0.67974396" ixy="0.04508972" ixz="0.00009980" iyy="0.83229961" iyz="0.00011851" izz="1.32231171" />
        </inertial>
        <visual>
            <origin rpy="0 0 0" xyz="0 0 0" />
            <geometry>
                <mesh filename="package://nj_220_2_7_description/meshes/link_5.STL" />
            </geometry>
            <material name="">
                <color rgba="1 0 0 1" />
            </material>
        </visual>
        <collision>
            <origin rpy="0 0 0" xyz="0 0 0" />
            <geometry>
                <mesh filename="package://nj_220_2_7_description/meshes/link_5.STL" />
            </geometry>
        </collision>
    </link>
    <joint name="nj_joint_5" type="revolute">
        <origin rpy="0 0 0" xyz="1.02033 0 0" />
        <parent link="nj_link_4" />
        <child link="nj_link_5" />
        <axis xyz="0 1 0" />
        <limit effort="1230" lower="-2.1816" upper="2.1816" velocity="2.26893" />
    </joint>
    <link name="nj_link_6">
        <inertial>
            <origin rpy="0 0 0" xyz="0.0058594 -0.00060952 -5.99E-05" />
            <mass value="5.3437" />
            <inertia ixx="0.02913604" ixy="-0.00000822" ixz="-0.00000086" iyy="0.01533002" iyz="0.00000585" izz="0.01518874" />
        </inertial>
        <visual>
            <origin rpy="0 0 0" xyz="0 0 0" />
            <geometry>
                <mesh filename="package://nj_220_2_7_description/meshes/link_6.STL" />
            </geometry>
            <material name="">
                <color rgba="0.25098 0.25098 0.25098 1" />
            </material>
        </visual>
        <collision>
            <origin rpy="0 0 0" xyz="0 0 0" />
            <geometry>
                <mesh filename="package://nj_220_2_7_description/meshes/link_6.STL" />
            </geometry>
        </collision>
    </link>
    <joint name="nj_joint_6" type="revolute">
        <origin rpy="0 0 0" xyz="0.2085 0 0" />
        <parent link="nj_link_5" />
        <child link="nj_link_6" />
        <axis xyz="1 0 0" />
        <limit effort="712" lower="-6.2831853" upper="6.2831853" velocity="3.40339" />
    </joint>
    <link name="nj_link_2_1">
        <inertial>
            <origin rpy="0 0 0" xyz="-0.14831 0.02392 -0.01938" />
            <mass value="41.905" />
            <inertia ixx="0.20904736" ixy="-0.17095810" ixz="0.20186889" iyy="1.77577938" iyz="-0.02155338" izz="1.68515339" />
        </inertial>
        <visual>
            <origin rpy="0 0 0" xyz="0 0 0" />
            <geometry>
                <mesh filename="package://nj_220_2_7_description/meshes/link_2_1.STL" />
            </geometry>
            <material name="">
                <color rgba="1 0 0 1" />
            </material>
        </visual>
        <collision>
            <origin rpy="0 0 0" xyz="0 0 0" />
            <geometry>
                <mesh filename="package://nj_220_2_7_description/meshes/link_2_1.STL" />
            </geometry>
        </collision>
    </link>
    <link name="nj_link_2_2">
        <!-- <inertial>
      <origin
        xyz="-0.06443 0.01485 0.51885"
        rpy="0 0 0" />
      <mass
        value="60.72" />
      <inertia
        ixx="21.93937071"
        ixy="-0.05733724"
        ixz="-1.89190480"
        iyy="22.27041146"
        iyz="0.47064670"
        izz="0.41028863" />
    </inertial> -->
        <inertial>
            <origin rpy="0 0 0" xyz="0 0 0" />
            <mass value="0.01" />
            <inertia ixx="0.00001" ixy="0.00000" ixz="0.00000" iyy="0.00001" iyz="0.00000" izz="0.00000" />
        </inertial>
        <visual>
            <origin rpy="0 0 0" xyz="0 0 0" />
            <geometry>
                <mesh filename="package://nj_220_2_7_description/meshes/link_2_2.STL" />
            </geometry>
        </visual>
        <collision>
            <origin rpy="0 0 0" xyz="0 0 0" />
            <geometry>
                <mesh filename="package://nj_220_2_7_description/meshes/link_2_2.STL" />
            </geometry>
        </collision>
    </link>
    <joint name="nj_joint_3m" type="revolute">
        <origin rpy="0 0 0" xyz="0.400 -0.1945 0.499" />
        <parent link="nj_link_1" />
        <child link="nj_link_2_1" />
        <axis xyz="0 -1 0" />
        <limit effort="0" lower="-6.2831853" upper="6.2831853" velocity="0" />
        <mimic joint="nj_joint_3" multiplier="1" offset="0" />
    </joint>
    <link name="nj_link_2_2_virtual">
        <inertial>
            <origin rpy="0 0 0" xyz="0 0 0" />
            <mass value="0.01" />
            <inertia ixx="0.00001" ixy="0.00000" ixz="0.00000" iyy="0.00001" iyz="0.00000" izz="0.00000" />
        </inertial>
        <collision>
            <origin rpy="0 0 0" xyz="0 0.05 0" />
            <geometry>
                <box size="0.01 0.1 0.01" />
            </geometry>
            <material name="aluminium">
                <color rgba="0.515625 0.52734375 0.53515625 1" />
            </material>
        </collision>
    </link>
    <joint name="nj_joint_2_1" type="continuous">
        <origin rpy="0 0 0" xyz="-0.34867 0.015 -0.0305" />
        <parent link="nj_link_2_1" />
        <child link="nj_link_2_2_virtual" />
        <axis xyz="0 1 0" />
        <mimic joint="nj_joint_3" multiplier="1" offset="0" />
    </joint>
    <joint name="nj_joint_2_2" type="continuous">
        <origin rpy="0 0 0" xyz="0.0 0.0 0.0" />
        <parent link="nj_link_2_2_virtual" />
        <child link="nj_link_2_2" />
        <axis xyz="0 1 0" />
        <mimic joint="nj_joint_2" multiplier="1" offset="0" />
    </joint>
    <link name="nj_link_2_3">
        <inertial>
            <origin rpy="0 0 0" xyz="0 0 0" />
            <mass value="0.01" />
            <inertia ixx="0.00001" ixy="0.00000" ixz="0.00000" iyy="0.00001" iyz="0.00000" izz="0.00000" />
        </inertial>
        <collision>
            <origin rpy="0 0 0" xyz="0 0 0" />
            <geometry>
                <box size="0.01 0.5 0.01" />
            </geometry>
            <material name="aluminium">
                <color rgba="0.515625 0.52734375 0.53515625 1" />
            </material>
        </collision>
    </link>
    <joint name="nj_joint_2_3" type="continuous">
        <origin rpy="0 0 0" xyz="0 0 1.175" />
        <parent link="nj_link_2_2" />
        <child link="nj_link_2_3" />
        <axis xyz="0 1 0" />
        <limit effort="0" lower="-6.2831853" upper="6.2831853" velocity="0" />
    </joint>
    <link name="nj_link_2_4">
        <inertial>
            <origin rpy="0 0 0" xyz="0 0 0" />
            <mass value="0.01" />
            <inertia ixx="0.00001" ixy="0.00000" ixz="0.00000" iyy="0.00001" iyz="0.00000" izz="0.00000" />
        </inertial>
        <collision>
            <origin rpy="0 0 0" xyz="0 0 0" />
            <geometry>
                <box size="0.01 0.5 0.01" />
            </geometry>
            <material name="aluminium">
                <color rgba="0.515625 0.52734375 0.53515625 1" />
            </material>
        </collision>
    </link>
    <joint name="nj_joint_2_4" type="fixed">
        <origin rpy="0 0 0" xyz="-0.34867 -0.1795 -0.0305" />
        <!-- <origin xyz="0 0 0" rpy="0 0 0" /> -->
        <parent link="nj_link_3" />
        <child link="nj_link_2_4" />
        <axis xyz="0 1 0" />
    </joint>
    <link name="nj_flange">
        <inertial>
            <origin rpy="0 0 0" xyz="0 0 0" />
            <mass value="0.01" />
            <inertia ixx="0.00001" ixy="0.00000" ixz="0.00000" iyy="0.00001" iyz="0.00000" izz="0.00000" />
        </inertial>
    </link>
    <joint name="nj_link_6_to_flange" type="fixed">
        <origin rpy="0 0 0" xyz="0 0 -0.0395" />
        <parent link="nj_link_6" />
        <child link="nj_flange" />
        <axis xyz="0 0 0" />
    </joint>
    <!-- Stroke Ends -->
    <link name="nj_external_piece">
        <inertial>
            <origin rpy="0 0 0" xyz="0.25149 0 0.08305" />
            <mass value="11.17" />
            <inertia ixx="0.12505051" ixy="0" ixz="0.20615167" iyy="0.86139689" iyz="0" izz="0.75193919" />
        </inertial>
        <visual>
            <origin rpy="0 0 0" xyz="0 0 0" />
            <geometry>
                <mesh filename="package://nj_220_2_7_description/meshes/external_part.STL" />
            </geometry>
        </visual>
        <collision>
            <origin rpy="0 0 0" xyz="0 0 0" />
            <geometry>
                <mesh filename="package://nj_220_2_7_description/meshes/external_part.STL" />
            </geometry>
        </collision>
    </link>
    <joint name="nj_joint_external_piece" type="fixed">
        <origin rpy="0 0 0" xyz="0 0 0" />
        <parent link="nj_link_1" />
        <child link="nj_external_piece" />
        <axis xyz="0 0 0" />
    </joint>
    <link name="nj_motor_1">
        <inertial>
            <origin rpy="0 0 0" xyz="0 0.00059 -0.13134" />
            <mass value="74.18" />
            <inertia ixx="2.03862179" ixy="0.00000294" ixz="0.00001194" iyy="2.03393681" iyz="-0.01109897" izz="0.37378121" />
        </inertial>
        <visual>
            <origin rpy="0 0 0" xyz="0 0 0" />
            <geometry>
                <mesh filename="package://nj_220_2_7_description/meshes/motor_80.STL" />
            </geometry>
        </visual>
        <collision>
            <origin rpy="0 0 0" xyz="0 0 0" />
            <geometry>
                <mesh filename="package://nj_220_2_7_description/meshes/motor_80.STL" />
            </geometry>
        </collision>
    </link>
    <joint name="nj_joint_motor_1" type="fixed">
        <origin rpy="0 0 4.194026193" xyz="-0.1567 0.0905 0.12075" />
        <parent link="nj_link_1" />
        <child link="nj_motor_1" />
        <axis xyz="0 0 0" />
    </joint>
    <link name="nj_motor_2">
        <inertial>
            <origin rpy="0 0 0" xyz="0 0.00055 -0.14385" />
            <mass value="80.26" />
            <inertia ixx="2.5764983" ixy="0.00000380" ixz="0.01312758" iyy="2.49873445" iyz="-0.0000105" izz="0.40399789" />
        </inertial>
        <visual>
            <origin rpy="0 0 0" xyz="0 0 0" />
            <geometry>
                <mesh filename="package://nj_220_2_7_description/meshes/motor_90.STL" />
            </geometry>
        </visual>
        <collision>
            <origin rpy="0 0 0" xyz="0 0 0" />
            <geometry>
                <mesh filename="package://nj_220_2_7_description/meshes/motor_90.STL" />
            </geometry>
        </collision>
    </link>
    <joint name="nj_joint_motor_2" type="fixed">
        <origin rpy="-1.570796327 1.570796327 0" xyz="0.400 0.2955 0.499" />
        <parent link="nj_link_1" />
        <child link="nj_motor_2" />
        <axis xyz="0 0 0" />
    </joint>
    <link name="nj_motor_3">
        <inertial>
            <origin rpy="0 0 0" xyz="0 0.00059 -0.13134" />
            <mass value="74.18" />
            <inertia ixx="2.03862179" ixy="0.00000294" ixz="0.00001194" iyy="2.03393681" iyz="-0.01109897" izz="0.37378121" />
        </inertial>
        <visual>
            <origin rpy="0 0 0" xyz="0 0 0" />
            <geometry>
                <mesh filename="package://nj_220_2_7_description/meshes/motor_80.STL" />
            </geometry>
        </visual>
        <collision>
            <origin rpy="0 0 0" xyz="0 0 0" />
            <geometry>
                <mesh filename="package://nj_220_2_7_description/meshes/motor_80.STL" />
            </geometry>
        </collision>
    </link>
    <joint name="nj_joint_motor_3" type="fixed">
        <origin rpy="1.570796327 1.570796327 0" xyz="0.400 -0.358 0.499" />
        <parent link="nj_link_1" />
        <child link="nj_motor_3" />
        <axis xyz="0 0 0" />
    </joint>
    <link name="nj_motor_4">
        <inertial>
            <origin rpy="0 0 0" xyz="0.00125 0 -0.0852" />
            <mass value="28" />
            <inertia ixx="0.33783188" ixy="-0.00000254" ixz="-0.00532880" iyy="0.34073438" iyz="0.00000366" izz="0.08086422" />
        </inertial>
        <visual>
            <origin rpy="0 0 0" xyz="0 0 0" />
            <geometry>
                <mesh filename="package://nj_220_2_7_description/meshes/motor_50.STL" />
            </geometry>
        </visual>
        <collision>
            <origin rpy="0 0 0" xyz="0 0 0" />
            <geometry>
                <mesh filename="package://nj_220_2_7_description/meshes/motor_50.STL" />
            </geometry>
        </collision>
    </link>
    <joint name="nj_joint_motor_4" type="fixed">
        <origin rpy="3.141592654 1.570796327 0" xyz="-0.200 0.21052 0.175" />
        <parent link="nj_link_3" />
        <child link="nj_motor_4" />
        <axis xyz="0 -1 0" />
    </joint>
    <link name="nj_motor_5">
        <inertial>
            <origin rpy="0 0 0" xyz="0.00125 0 -0.0852" />
            <mass value="28" />
            <inertia ixx="0.33783188" ixy="-0.00000254" ixz="-0.00532880" iyy="0.34073438" iyz="0.00000366" izz="0.08086422" />
        </inertial>
        <visual>
            <origin rpy="0 0 0" xyz="0 0 0" />
            <geometry>
                <mesh filename="package://nj_220_2_7_description/meshes/motor_50.STL" />
            </geometry>
        </visual>
        <collision>
            <origin rpy="0 0 0" xyz="0 0 0" />
            <geometry>
                <mesh filename="package://nj_220_2_7_description/meshes/motor_50.STL" />
            </geometry>
        </collision>
    </link>
    <joint name="nj_joint_motor_5" type="fixed">
        <origin rpy="1.570796327 0 -1.570796327" xyz="-0.1675 0 0.250" />
        <parent link="nj_link_3" />
        <child link="nj_motor_5" />
        <axis xyz="0 -1 0" />
    </joint>
    <link name="nj_motor_6">
        <inertial>
            <origin rpy="0 0 0" xyz="0.00125 0 -0.0852" />
            <mass value="28" />
            <inertia ixx="0.33783188" ixy="-0.00000254" ixz="-0.00532880" iyy="0.34073438" iyz="0.00000366" izz="0.08086422" />
        </inertial>
        <visual>
            <origin rpy="0 0 0" xyz="0 0 0" />
            <geometry>
                <mesh filename="package://nj_220_2_7_description/meshes/motor_50.STL" />
            </geometry>
        </visual>
        <collision>
            <origin rpy="0 0 0" xyz="0 0 0" />
            <geometry>
                <mesh filename="package://nj_220_2_7_description/meshes/motor_50.STL" />
            </geometry>
        </collision>
    </link>
    <joint name="nj_joint_motor_6" type="fixed">
        <origin rpy="-1.570796327 0 1.570796327" xyz="-0.1675 0.155 0.34577" />
        <parent link="nj_link_3" />
        <child link="nj_motor_6" />
        <axis xyz="0 -1 0" />
    </joint>
    <!-- End Stroke End -->
    <transmission name="nj_tran_1">
        <type>transmission_interface/SimpleTransmission</type>
        <joint name="nj_joint_1">
            <hardwareInterface>hardware_interface/EffortJointInterface</hardwareInterface>
        </joint>
        <actuator name="nj_motor_1">
            <mechanicalReduction>1</mechanicalReduction>
            <hardwareInterface>hardware_interface/EffortJointInterface</hardwareInterface>
        </actuator>
    </transmission>
    <transmission name="nj_tran_2">
        <type>transmission_interface/SimpleTransmission</type>
        <joint name="nj_joint_2">
            <hardwareInterface>hardware_interface/EffortJointInterface</hardwareInterface>
        </joint>
        <actuator name="nj_motor_2">
            <mechanicalReduction>1</mechanicalReduction>
            <hardwareInterface>hardware_interface/EffortJointInterface</hardwareInterface>
        </actuator>
    </transmission>
    <transmission name="nj_tran_3">
        <type>transmission_interface/SimpleTransmission</type>
        <joint name="nj_joint_3">
            <hardwareInterface>hardware_interface/EffortJointInterface</hardwareInterface>
        </joint>
        <actuator name="nj_motor_3">
            <mechanicalReduction>1</mechanicalReduction>
            <hardwareInterface>hardware_interface/EffortJointInterface</hardwareInterface>
        </actuator>
    </transmission>
    <transmission name="nj_tran_4">
        <type>transmission_interface/SimpleTransmission</type>
        <joint name="nj_joint_4">
            <hardwareInterface>hardware_interface/EffortJointInterface</hardwareInterface>
        </joint>
        <actuator name="nj_motor_4">
            <mechanicalReduction>1</mechanicalReduction>
            <hardwareInterface>hardware_interface/EffortJointInterface</hardwareInterface>
        </actuator>
    </transmission>
    <transmission name="nj_tran_5">
        <type>transmission_interface/SimpleTransmission</type>
        <joint name="nj_joint_5">
            <hardwareInterface>hardware_interface/EffortJointInterface</hardwareInterface>
        </joint>
        <actuator name="nj_motor_5">
            <mechanicalReduction>1</mechanicalReduction>
            <hardwareInterface>hardware_interface/EffortJointInterface</hardwareInterface>
        </actuator>
    </transmission>
    <transmission name="nj_tran_6">
        <type>transmission_interface/SimpleTransmission</type>
        <joint name="nj_joint_6">
            <hardwareInterface>hardware_interface/EffortJointInterface</hardwareInterface>
        </joint>
        <actuator name="nj_motor_6">
            <mechanicalReduction>1</mechanicalReduction>
            <hardwareInterface>hardware_interface/EffortJointInterface</hardwareInterface>
        </actuator>
    </transmission>
    <joint name="world_to_nj_220_2_7" type="fixed">
        <origin rpy="0 0 0" xyz="-2 -2 0" />
        <parent link="world" />
        <child link="nj_base_link" />
    </joint>
    <link name="table_base_link" />
    <link name="table_leg1_link">
        <inertial>
            <origin rpy="0 0 0" xyz="0 0 0.45" />
            <mass value="9.573825" />
            <inertia ixx="0.649105335" ixy="0" ixz="0" iyy="0.649105335" iyz="0" izz="0.005744294999999999" />
        </inertial>
        <visual>
            <origin rpy="0 0 0" xyz="0 0 0.45" />
            <geometry>
                <box size="0.06 0.06 0.9" />
            </geometry>
            <material name="">
                <color rgba="0.1176 0.5059 0.6902 1" />
            </material>
        </visual>
        <collision>
            <origin rpy="0 0 0" xyz="0 0 0.45" />
            <geometry>
                <box size="0.06 0.06 0.9" />
            </geometry>
        </collision>
    </link>
    <joint name="table_base_to_leg1" type="fixed">
        <origin rpy="0 0 0" xyz="0.72 0.71 0" />
        <parent link="table_base_link" />
        <child link="table_leg1_link" />
    </joint>
    <link name="table_leg2_link">
        <inertial>
            <origin rpy="0 0 0" xyz="0 0 0.45" />
            <mass value="9.573825" />
            <inertia ixx="0.649105335" ixy="0" ixz="0" iyy="0.649105335" iyz="0" izz="0.005744294999999999" />
        </inertial>
        <visual>
            <origin rpy="0 0 0" xyz="0 0 0.45" />
            <geometry>
                <box size="0.06 0.06 0.9" />
            </geometry>
            <material name="">
                <color rgba="0.1176 0.5059 0.6902 1" />
            </material>
        </visual>
        <collision>
            <origin rpy="0 0 0" xyz="0 0 0.45" />
            <geometry>
                <box size="0.06 0.06 0.9" />
            </geometry>
        </collision>
    </link>
    <joint name="table_base_to_leg2" type="fixed">
        <origin rpy="0 0 0" xyz="0.72 -0.71 0" />
        <parent link="table_base_link" />
        <child link="table_leg2_link" />
    </joint>
    <link name="table_leg3_link">
        <inertial>
            <origin rpy="0 0 0" xyz="0 0 0.45" />
            <mass value="9.573825" />
            <inertia ixx="0.649105335" ixy="0" ixz="0" iyy="0.649105335" iyz="0" izz="0.005744294999999999" />
        </inertial>
        <visual>
            <origin rpy="0 0 0" xyz="0 0 0.45" />
            <geometry>
                <box size="0.06 0.06 0.9" />
            </geometry>
            <material name="">
                <color rgba="0.1176 0.5059 0.6902 1" />
            </material>
        </visual>
        <collision>
            <origin rpy="0 0 0" xyz="0 0 0.45" />
            <geometry>
                <box size="0.06 0.06 0.9" />
            </geometry>
        </collision>
    </link>
    <joint name="table_base_to_leg3" type="fixed">
        <origin rpy="0 0 0" xyz="-0.72 -0.71 0" />
        <parent link="table_base_link" />
        <child link="table_leg3_link" />
    </joint>
    <link name="table_leg4_link">
        <inertial>
            <origin rpy="0 0 0" xyz="0 0 0.45" />
            <mass value="9.573825" />
            <inertia ixx="0.649105335" ixy="0" ixz="0" iyy="0.649105335" iyz="0" izz="0.005744294999999999" />
        </inertial>
        <visual>
            <origin rpy="0 0 0" xyz="0 0 0.45" />
            <geometry>
                <box size="0.06 0.06 0.9" />
            </geometry>
            <material name="">
                <color rgba="0.1176 0.5059 0.6902 1" />
            </material>
        </visual>
        <collision>
            <origin rpy="0 0 0" xyz="0 0 0.45" />
            <geometry>
                <box size="0.06 0.06 0.9" />
            </geometry>
        </collision>
    </link>
    <joint name="table_base_to_leg4" type="fixed">
        <origin rpy="0 0 0" xyz="-0.72 0.71 0" />
        <parent link="table_base_link" />
        <child link="table_leg4_link" />
    </joint>
    <link name="table_tabletop_link">
        <inertial>
            <origin rpy="0 0 0" xyz="0 0 0.0075" />
            <mass value="9.573825" />
            <inertia ixx="47.774738203125" ixy="0" ixz="0" iyy="49.074538213124995" iyz="0" izz="96.83946249" />
        </inertial>
        <visual>
            <origin rpy="0 0 0" xyz="0 0 0.0075" />
            <geometry>
                <box size="1.5 1.48 0.015" />
            </geometry>
            <material name="">
                <color rgba="0.6608 0.6608 0.7878 1" />
            </material>
        </visual>
        <collision>
            <origin rpy="0 0 0" xyz="0 0 0.0075" />
            <geometry>
                <box size="1.5 1.48 0.015" />
            </geometry>
        </collision>
    </link>
    <joint name="table_base_to_tabletop" type="fixed">
        <origin rpy="0 0 0" xyz="0 0 0.9" />
        <parent link="table_base_link" />
        <child link="table_tabletop_link" />
    </joint>
    <joint name="world_to_table" type="fixed">
        <origin rpy="0 0 0" xyz="1 -1 0" />
        <parent link="world" />
        <child link="table_base_link" />
    </joint>
    <link name="omron_base_link" />
    <link name="omron_base_x" />
    <joint name="omron_joint_x" type="prismatic">
        <origin rpy="0 0 0" xyz="0 0 0" />
        <parent link="omron_base_link" />
        <child link="omron_base_x" />
        <axis xyz="1 0 0" />
        <limit effort="1000" lower="-4.5" upper="0.5" velocity="2" />
    </joint>
    <link name="omron_base_y" />
    <joint name="omron_joint_y" type="prismatic">
        <origin rpy="0 0 0" xyz="0 0 0" />
        <parent link="omron_base_x" />
        <child link="omron_base_y" />
        <axis xyz="0 1 0" />
        <limit effort="1000" lower="-1" upper="3" velocity="2" />
    </joint>
    <!-- Base footprint is on the ground under the robot -->
    <!-- <link name="${prefix}base_footprint">
      <inertial>
          <mass value="1000" />
          <inertia ixx="0.001" ixy="0.01" ixz="0.01" iyy="0.001" iyz="0.01" izz="0.001" />
      </inertial>
    </link>   -->
    <!-- Base link is the center of the robot's bottom plate -->
    <link name="omron_agv_base_link">
        <visual>
            <origin rpy="1.570795 0 1.570795" xyz="0 0 0.2" />
            <geometry>
                <mesh filename="file:///home/abel/projects/personal_ws/src/omron_agv_manipulator/omron_agv_description//mesh/LD60.stl" />
            </geometry>
            <material name="Gray">
                <color rgba="0.5 0.5 0.5 1.0" />
            </material>
        </visual>
        <collision>
            <origin rpy="1.570795 0 1.570795" xyz="0 0 0.2" />
            <geometry>
                <mesh filename="file:///home/abel/projects/personal_ws/src/omron_agv_manipulator/omron_agv_description//mesh/LD60.stl" />
            </geometry>
            <material name="Gray">
                <color rgba="0.5 0.5 0.5 1.0" />
            </material>
        </collision>
        <inertial>
            <mass value="4000" />
            <inertia ixx="1.48454" ixy="0.01" ixz="0.01" iyy="3.02861" iyz="0.01" izz="4.10178" />
            <origin xyz="0 0 0" rpy="0 0 0" />
        </inertial>
    </link>
    <!-- <joint name="${prefix}base_footprint_joint" type="fixed">
      <xacro:insert_block name="origin"/>
      <parent link="${prefix}base_link" />
      <child link="${prefix}base_footprint" />
    </joint> -->
    <joint name="omron_joint_rev" type="revolute">
        <origin rpy="0 0 0" xyz="0 0 0" />
        <parent link="omron_base_y" />
        <child link="omron_agv_base_link" />
        <axis xyz="0 0 1" />
        <limit effort="1000" lower="-3.14159" upper="3.14159" velocity="3.14159" />
    </joint>
    <gazebo reference="omron_arm_link_1">
        <selfCollide>true</selfCollide>
    </gazebo>
    <gazebo reference="omron_arm_link_2">
        <selfCollide>true</selfCollide>
    </gazebo>
    <gazebo reference="omron_arm_link_3">
        <selfCollide>true</selfCollide>
    </gazebo>
    <gazebo reference="omron_arm_link_4">
        <selfCollide>true</selfCollide>
    </gazebo>
    <gazebo reference="omron_arm_link_5">
        <selfCollide>true</selfCollide>
    </gazebo>
    <gazebo reference="omron_arm_link_6">
        <selfCollide>true</selfCollide>
    </gazebo>
    <gazebo>
        <plugin filename="libgazebo_ros_control.so" name="gazebo_ros_control">
            <robotNamespace>/omron/</robotNamespace>
            <robotSimType>gazebo_ros_control/DefaultRobotHWSim</robotSimType>
        </plugin>
    </gazebo>
    <transmission name="omron_arm_trans_1">
        <type>transmission_interface/SimpleTransmission</type>
        <joint name="omron_arm_joint_1">
            <hardwareInterface>hardware_interface/PositionJointInterface</hardwareInterface>
        </joint>
        <actuator name="omron_arm_motor_1">
            <mechanicalReduction>1</mechanicalReduction>
            <hardwareInterface>hardware_interface/EffortJointInterface</hardwareInterface>
        </actuator>
    </transmission>
    <transmission name="omron_arm_trans_2">
        <type>transmission_interface/SimpleTransmission</type>
        <joint name="omron_arm_joint_2">
            <hardwareInterface>hardware_interface/PositionJointInterface</hardwareInterface>
        </joint>
        <actuator name="omron_arm_motor_2">
            <mechanicalReduction>1</mechanicalReduction>
            <hardwareInterface>hardware_interface/EffortJointInterface</hardwareInterface>
        </actuator>
    </transmission>
    <transmission name="omron_arm_trans_3">
        <type>transmission_interface/SimpleTransmission</type>
        <joint name="omron_arm_joint_3">
            <hardwareInterface>hardware_interface/PositionJointInterface</hardwareInterface>
        </joint>
        <actuator name="omron_arm_motor_3">
            <mechanicalReduction>1</mechanicalReduction>
            <hardwareInterface>hardware_interface/EffortJointInterface</hardwareInterface>
        </actuator>
    </transmission>
    <transmission name="omron_arm_trans_4">
        <type>transmission_interface/SimpleTransmission</type>
        <joint name="omron_arm_joint_4">
            <hardwareInterface>hardware_interface/PositionJointInterface</hardwareInterface>
        </joint>
        <actuator name="omron_arm_motor_4">
            <mechanicalReduction>1</mechanicalReduction>
            <hardwareInterface>hardware_interface/EffortJointInterface</hardwareInterface>
        </actuator>
    </transmission>
    <transmission name="omron_arm_trans_5">
        <type>transmission_interface/SimpleTransmission</type>
        <joint name="omron_arm_joint_5">
            <hardwareInterface>hardware_interface/PositionJointInterface</hardwareInterface>
        </joint>
        <actuator name="omron_arm_motor_5">
            <mechanicalReduction>1</mechanicalReduction>
            <hardwareInterface>hardware_interface/EffortJointInterface</hardwareInterface>
        </actuator>
    </transmission>
    <transmission name="omron_arm_trans_6">
        <type>transmission_interface/SimpleTransmission</type>
        <joint name="omron_arm_joint_6">
            <hardwareInterface>hardware_interface/PositionJointInterface</hardwareInterface>
        </joint>
        <actuator name="omron_arm_motor_6">
            <mechanicalReduction>1</mechanicalReduction>
            <hardwareInterface>hardware_interface/EffortJointInterface</hardwareInterface>
        </actuator>
    </transmission>
    <material name="none">
        <color rgba="0.0 0.0 0.0 1.0" />
    </material>
    <material name="lightgrey">
        <color rgba="0.5 0.5 0.5 1.0" />
    </material>
    <material name="grey">
        <color rgba="0.75 0.75 0.75 1.0" />
    </material>
    <material name="white">
        <color rgba="0.95 0.95 0.95 1.0" />
    </material>
    <material name="red">
        <color rgba="0.95 0.0 0.0 1.0" />
    </material>
    <material name="orange">
        <color rgba="1.0 0.5 0.0 1.0" />
    </material>
    <material name="yellow">
        <color rgba="1.0 1.0 0.0 1.0" />
    </material>
    <material name="green">
        <color rgba="0.0 1.0 0.0 1.0" />
    </material>
    <material name="blue">
        <color rgba="0.0 0.0 1.0 1.0" />
    </material>
    <material name="indigo">
        <color rgba="0.3 0.3 0.6 1.0" />
    </material>
    <material name="violet">
        <color rgba="0.6 0.0 1.0 1.0" />
    </material>
    <material name="black">
        <color rgba="0.0 0.0 0.0 1.0" />
    </material>
    <material name="darkolive">
        <color rgba="0.3 0.3 0.25 1.0" />
    </material>
    <ros2_control name="tm12" type="system">
        <hardware>
            <plugin>tm_robot_driver/TMPositionHardwareInterface</plugin>
        </hardware>
        <joint name="omron_arm_joint_1">
            <command_interface name="position">
                <param name="min">-4.71238898038469</param>
                <param name="max">4.71238898038469</param>
            </command_interface>
            <command_interface name="velocity" />
            <state_interface name="position" />
            <state_interface name="velocity" />
            <state_interface name="effort" />
        </joint>
        <joint name="omron_arm_joint_2">
            <command_interface name="position">
                <param name="min">-3.141592653589793</param>
                <param name="max">3.141592653589793</param>
            </command_interface>
            <command_interface name="velocity" />
            <state_interface name="position" />
            <state_interface name="velocity" />
            <state_interface name="effort" />
        </joint>
        <joint name="omron_arm_joint_3">
            <command_interface name="position">
                <param name="min">-2.897246558310587</param>
                <param name="max">-2.897246558310587</param>
            </command_interface>
            <command_interface name="velocity" />
            <state_interface name="position" />
            <state_interface name="velocity" />
            <state_interface name="effort" />
        </joint>
        <joint name="omron_arm_joint_4">
            <command_interface name="position">
                <param name="min">-3.141592653589793</param>
                <param name="max">3.141592653589793</param>
            </command_interface>
            <command_interface name="velocity" />
            <state_interface name="position" />
            <state_interface name="velocity" />
            <state_interface name="effort" />
        </joint>
        <joint name="omron_arm_joint_5">
            <command_interface name="position">
                <param name="min">-3.141592653589793</param>
                <param name="max">3.141592653589793</param>
            </command_interface>
            <command_interface name="velocity" />
            <state_interface name="position" />
            <state_interface name="velocity" />
            <state_interface name="effort" />
        </joint>
        <joint name="omron_arm_joint_6">
            <command_interface name="position">
                <param name="min">-4.71238898038469</param>
                <param name="max">-4.71238898038469</param>
            </command_interface>
            <command_interface name="velocity" />
            <state_interface name="position" />
            <state_interface name="velocity" />
            <state_interface name="effort" />
        </joint>
    </ros2_control>
    <!--LinkDescription-->
    <link name="omron_arm_link_0">
        <visual>
            <geometry>
                <mesh filename="package://tm_description/meshes/tm12/visual/tm12-base.obj" />
            </geometry>
            <material name="none" />
        </visual>
        <collision>
            <geometry>
                <mesh filename="package://tm_description/meshes/tm12/collision/tm12-base_c.stl" />
            </geometry>
        </collision>
        <inertial>
            <mass value="1.0" />
            <origin rpy="0.000000 0.000000 0.000000" xyz="0.000000 0.000000 0.000000" />
            <inertia ixx="0.00110833289" ixy="0.0" ixz="0.0" iyy="0.00110833289" iyz="0.0" izz="0.0018" />
        </inertial>
    </link>
    <joint name="omron_arm_joint_1" type="revolute">
        <parent link="omron_arm_link_0" />
        <child link="omron_arm_link_1" />
        <origin rpy="0.000000 -0.000000 0.000000" xyz="0.000000 0.000000 0.165200" />
        <axis xyz="0 0 1" />
        <!--limit-->
        <limit effort="353" lower="-4.71238898038469" upper="4.71238898038469" velocity="2.0943951023931953" />
        <dynamics damping="0.0" friction="0.0" />
    </joint>
    <link name="omron_arm_link_1">
        <visual>
            <geometry>
                <mesh filename="package://tm_description/meshes/tm12/visual/tmr_750w_01.obj" />
            </geometry>
            <material name="none" />
        </visual>
        <collision>
            <geometry>
                <mesh filename="package://tm_description/meshes/tm12/collision/tmr_750w_01_c.stl" />
            </geometry>
        </collision>
        <inertial>
            <origin rpy="0.000000 0.000000 0.000000" xyz="0.000000 0.000000 0.000000" />
            <mass value="7.6" />
            <inertia ixx="0.020289334" ixy="0.000000" ixz="0.000000" iyy="0.020289334" iyz="0.000000" izz="0.021396270999999998" />
        </inertial>
    </link>
    <joint name="omron_arm_joint_2" type="revolute">
        <parent link="omron_arm_link_1" />
        <child link="omron_arm_link_2" />
        <origin rpy="-1.570796 -1.570796 0.000000" xyz="0.000000 0.000000 0.000000" />
        <axis xyz="0 0 1" />
        <!--limit-->
        <limit effort="353" lower="-3.141592653589793" upper="3.141592653589793" velocity="2.0943951023931953" />
        <dynamics damping="0.0" friction="0.0" />
    </joint>
    <link name="omron_arm_link_2">
        <visual>
            <geometry>
                <mesh filename="package://tm_description/meshes/tm12/visual/tm12-arm1.obj" />
            </geometry>
            <material name="none" />
        </visual>
        <collision>
            <geometry>
                <mesh filename="package://tm_description/meshes/tm12/collision/tm12-arm1_c.stl" />
            </geometry>
        </collision>
        <inertial>
            <origin rpy="0.000000 0.000000 0.000000" xyz="0.000000 0.000000 0.000000" />
            <mass value="14.0239" />
            <inertia ixx="0.071505715" ixy="0.000000" ixz="0.000000" iyy="1.1758788999999998" iyz="0.000000" izz="1.2033932999999999" />
        </inertial>
    </link>
    <joint name="omron_arm_joint_3" type="revolute">
        <parent link="omron_arm_link_2" />
        <child link="omron_arm_link_3" />
        <origin rpy="0.000000 -0.000000 0.000000" xyz="0.636100 0.000000 0.000000" />
        <axis xyz="0 0 1" />
        <!--limit-->
        <limit effort="157" lower="-2.897246558310587" upper="2.897246558310587" velocity="3.141592653589793" />
        <dynamics damping="0.0" friction="0.0" />
    </joint>
    <link name="omron_arm_link_3">
        <visual>
            <geometry>
                <mesh filename="package://tm_description/meshes/tm12/visual/tm12-arm2.obj" />
            </geometry>
            <material name="none" />
        </visual>
        <collision>
            <geometry>
                <mesh filename="package://tm_description/meshes/tm12/collision/tm12-arm2_c.stl" />
            </geometry>
        </collision>
        <inertial>
            <origin rpy="0.000000 0.000000 0.000000" xyz="0.000000 0.000000 0.000000" />
            <mass value="3.3577" />
            <inertia ixx="0.009755469" ixy="0.000000" ixz="0.000000" iyy="0.16334719" iyz="0.000000" izz="0.16656678" />
        </inertial>
    </link>
    <joint name="omron_arm_joint_4" type="revolute">
        <parent link="omron_arm_link_3" />
        <child link="omron_arm_link_4" />
        <origin rpy="0.000000 -0.000000 1.570796" xyz="0.557900 0.000000 -0.156300" />
        <axis xyz="0 0 1" />
        <!--limit-->
        <limit effort="54" lower="-3.141592653589793" upper="3.141592653589793" velocity="3.141592653589793" />
        <dynamics damping="0.0" friction="0.0" />
    </joint>
    <link name="omron_arm_link_4">
        <visual>
            <geometry>
                <mesh filename="package://tm_description/meshes/tm5-900/visual/tmr_100w_01.obj" />
            </geometry>
            <material name="none" />
        </visual>
        <collision>
            <geometry>
                <mesh filename="package://tm_description/meshes/tm5-900/collision/tmr_100w_01_c.stl" />
            </geometry>
        </collision>
        <inertial>
            <origin rpy="0.000000 0.000000 0.000000" xyz="0.000000 0.000000 0.000000" />
            <mass value="1.576" />
            <inertia ixx="0.002058405" ixy="0.000000" ixz="0.000000" iyy="0.0025630790000000002" iyz="0.000000" izz="0.00264321" />
        </inertial>
    </link>
    <joint name="omron_arm_joint_5" type="revolute">
        <parent link="omron_arm_link_4" />
        <child link="omron_arm_link_5" />
        <origin rpy="1.570796 -0.000000 0.000000" xyz="0.000000 -0.106000 0.000000" />
        <axis xyz="0 0 1" />
        <!--limit-->
        <limit effort="54" lower="-3.141592653589793" upper="3.141592653589793" velocity="3.141592653589793" />
        <dynamics damping="0.0" friction="0.0" />
    </joint>
    <link name="omron_arm_link_5">
        <visual>
            <geometry>
                <mesh filename="package://tm_description/meshes/tm5-900/visual/tmr_100w_02.obj" />
            </geometry>
            <material name="none" />
        </visual>
        <collision>
            <geometry>
                <mesh filename="package://tm_description/meshes/tm5-900/collision/tmr_100w_02_c.stl" />
            </geometry>
        </collision>
        <inertial>
            <origin rpy="0.000000 0.000000 0.000000" xyz="0.000000 0.000000 0.000000" />
            <mass value="1.576" />
            <inertia ixx="0.002058405" ixy="0.000000" ixz="0.000000" iyy="0.0025630790000000002" iyz="0.000000" izz="0.00264321" />
        </inertial>
    </link>
    <joint name="omron_arm_joint_6" type="revolute">
        <parent link="omron_arm_link_5" />
        <child link="omron_arm_link_6" />
        <origin rpy="1.570796 -0.000000 0.000000" xyz="0.000000 -0.113150 0.000000" />
        <axis xyz="0 0 1" />
        <!--limit-->
        <limit effort="54" lower="-4.71238898038469" upper="4.71238898038469" velocity="3.141592653589793" />
        <dynamics damping="0.0" friction="0.0" />
    </joint>
    <link name="omron_arm_link_6">
        <visual>
            <geometry>
                <mesh filename="package://tm_description/meshes/tm5-900/visual/tmr_ee.obj" />
            </geometry>
            <material name="none" />
        </visual>
        <collision>
            <geometry>
                <mesh filename="package://tm_description/meshes/tm5-900/collision/tmr_ee_c.stl" />
            </geometry>
        </collision>
        <inertial>
            <origin rpy="0.000000 0.000000 0.000000" xyz="0.000000 0.000000 0.000000" />
            <mass value="0.65" />
            <inertia ixx="0.000774544" ixy="0.000000" ixz="0.000000" iyy="0.0013838109999999998" iyz="0.000000" izz="0.001559496" />
        </inertial>
    </link>
    <link name="omron_arm_base_link" />
    <joint name="omron_arm_base_fixed_joint" type="fixed">
        <parent link="omron_arm_base_link" />
        <child link="omron_arm_link_0" />
        <origin rpy="0.000000 0.000000 0.000000" xyz="0.000000 0.000000 0.000000" />
    </joint>
    <link name="omron_arm_flange" />
    <joint name="omron_arm_flange_fixed_joint" type="fixed">
        <parent link="omron_arm_link_6" />
        <child link="omron_arm_flange" />
        <origin rpy="0.000000 0.000000 0.000000" xyz="0.000000 0.000000 0.000000" />
    </joint>
    <!--LinkDescription-->
    <!-- AGV-Arm joint -->
    <joint name="omron_lifter" type="fixed">
        <parent link="omron_agv_base_link" />
        <child link="omron_arm_base_link" />
        <origin rpy=" 0 0 0" xyz="0.2 -0.0 0.45" />
        <axis xyz="0 0 1" />
    </joint>
    <joint name="world_to_omron" type="fixed">
        <origin rpy="0 0 0" xyz="4.5 -3 0" />
        <parent link="world" />
        <child link="omron_base_link" />
    </joint>
    <gazebo>
        <plugin filename="libgazebo_ros_control.so" name="gazebo_ros_control">
            <robotNamespace>/gripper</robotNamespace>
            <robotSimType>gazebo_ros_control/DefaultRobotHWSim</robotSimType>
        </plugin>
    </gazebo>
    <transmission name="trans_kr_right_joint_1_2">
        <type>transmission_interface/SimpleTransmission</type>
        <joint name="kr_right_joint_1_2">
            <hardwareInterface>hardware_interface/EffortJointInterface</hardwareInterface>
        </joint>
        <actuator name="kr_right_joint_1_2_motor">
            <hardwareInterface>hardware_interface/EffortJointInterface</hardwareInterface>
            <mechanicalReduction>1</mechanicalReduction>
        </actuator>
    </transmission>
    <transmission name="trans_kr_right_joint_2_3">
        <type>transmission_interface/SimpleTransmission</type>
        <joint name="kr_right_joint_2_3">
            <hardwareInterface>hardware_interface/EffortJointInterface</hardwareInterface>
        </joint>
        <actuator name="kr_right_joint_2_3_motor">
            <hardwareInterface>hardware_interface/EffortJointInterface</hardwareInterface>
            <mechanicalReduction>1</mechanicalReduction>
        </actuator>
    </transmission>
    <transmission name="trans_kr_right_joint_3_4">
        <type>transmission_interface/SimpleTransmission</type>
        <joint name="kr_right_joint_3_4">
            <hardwareInterface>hardware_interface/EffortJointInterface</hardwareInterface>
        </joint>
        <actuator name="kr_right_joint_3_4_motor">
            <hardwareInterface>hardware_interface/EffortJointInterface</hardwareInterface>
            <mechanicalReduction>1</mechanicalReduction>
        </actuator>
    </transmission>
    <transmission name="trans_kr_left_joint_1_2">
        <type>transmission_interface/SimpleTransmission</type>
        <joint name="kr_left_joint_1_2">
            <hardwareInterface>hardware_interface/EffortJointInterface</hardwareInterface>
        </joint>
        <actuator name="kr_left_joint_1_2_motor">
            <hardwareInterface>hardware_interface/EffortJointInterface</hardwareInterface>
            <mechanicalReduction>1</mechanicalReduction>
        </actuator>
    </transmission>
    <transmission name="trans_kr_left_joint_2_3">
        <type>transmission_interface/SimpleTransmission</type>
        <joint name="kr_left_joint_2_3">
            <hardwareInterface>hardware_interface/EffortJointInterface</hardwareInterface>
        </joint>
        <actuator name="kr_left_joint_2_3_motor">
            <hardwareInterface>hardware_interface/EffortJointInterface</hardwareInterface>
            <mechanicalReduction>1</mechanicalReduction>
        </actuator>
    </transmission>
    <transmission name="trans_kr_left_joint_3_4">
        <type>transmission_interface/SimpleTransmission</type>
        <joint name="kr_left_joint_3_4">
            <hardwareInterface>hardware_interface/EffortJointInterface</hardwareInterface>
        </joint>
        <actuator name="kr_left_joint_3_4_motor">
            <hardwareInterface>hardware_interface/EffortJointInterface</hardwareInterface>
            <mechanicalReduction>1</mechanicalReduction>
        </actuator>
    </transmission>
    <transmission name="trans_nj_joint_2m">
        <type>transmission_interface/SimpleTransmission</type>
        <joint name="nj_joint_2m">
            <hardwareInterface>hardware_interface/EffortJointInterface</hardwareInterface>
        </joint>
        <actuator name="nj_joint_2m_motor">
            <hardwareInterface>hardware_interface/EffortJointInterface</hardwareInterface>
            <mechanicalReduction>1</mechanicalReduction>
        </actuator>
    </transmission>
    <transmission name="trans_nj_joint_3m">
        <type>transmission_interface/SimpleTransmission</type>
        <joint name="nj_joint_3m">
            <hardwareInterface>hardware_interface/EffortJointInterface</hardwareInterface>
        </joint>
        <actuator name="nj_joint_3m_motor">
            <hardwareInterface>hardware_interface/EffortJointInterface</hardwareInterface>
            <mechanicalReduction>1</mechanicalReduction>
        </actuator>
    </transmission>
    <transmission name="trans_nj_joint_2_1">
        <type>transmission_interface/SimpleTransmission</type>
        <joint name="nj_joint_2_1">
            <hardwareInterface>hardware_interface/EffortJointInterface</hardwareInterface>
        </joint>
        <actuator name="nj_joint_2_1_motor">
            <hardwareInterface>hardware_interface/EffortJointInterface</hardwareInterface>
            <mechanicalReduction>1</mechanicalReduction>
        </actuator>
    </transmission>
    <transmission name="trans_nj_joint_2_2">
        <type>transmission_interface/SimpleTransmission</type>
        <joint name="nj_joint_2_2">
            <hardwareInterface>hardware_interface/EffortJointInterface</hardwareInterface>
        </joint>
        <actuator name="nj_joint_2_2_motor">
            <hardwareInterface>hardware_interface/EffortJointInterface</hardwareInterface>
            <mechanicalReduction>1</mechanicalReduction>
        </actuator>
    </transmission>
    <transmission name="trans_nj_joint_2_3">
        <type>transmission_interface/SimpleTransmission</type>
        <joint name="nj_joint_2_3">
            <hardwareInterface>hardware_interface/EffortJointInterface</hardwareInterface>
        </joint>
        <actuator name="nj_joint_2_3_motor">
            <hardwareInterface>hardware_interface/EffortJointInterface</hardwareInterface>
            <mechanicalReduction>1</mechanicalReduction>
        </actuator>
    </transmission>
    <transmission name="trans_omron_joint_x">
        <type>transmission_interface/SimpleTransmission</type>
        <joint name="omron_joint_x">
            <hardwareInterface>hardware_interface/EffortJointInterface</hardwareInterface>
        </joint>
        <actuator name="omron_joint_x_motor">
            <hardwareInterface>hardware_interface/EffortJointInterface</hardwareInterface>
            <mechanicalReduction>1</mechanicalReduction>
        </actuator>
    </transmission>
    <transmission name="trans_omron_joint_y">
        <type>transmission_interface/SimpleTransmission</type>
        <joint name="omron_joint_y">
            <hardwareInterface>hardware_interface/EffortJointInterface</hardwareInterface>
        </joint>
        <actuator name="omron_joint_y_motor">
            <hardwareInterface>hardware_interface/EffortJointInterface</hardwareInterface>
            <mechanicalReduction>1</mechanicalReduction>
        </actuator>
    </transmission>
    <transmission name="trans_omron_joint_rev">
        <type>transmission_interface/SimpleTransmission</type>
        <joint name="omron_joint_rev">
            <hardwareInterface>hardware_interface/EffortJointInterface</hardwareInterface>
        </joint>
        <actuator name="omron_joint_rev_motor">
            <hardwareInterface>hardware_interface/EffortJointInterface</hardwareInterface>
            <mechanicalReduction>1</mechanicalReduction>
        </actuator>
    </transmission>
</robot>

